Workbook
Name _Toc26271466: Equipos!$G$35
Name HOMOL: '[1]TABLA DE NOMBRES'!#REF!
Name HOMOL: '[1]TABLA DE NOMBRES'!#REF!
Name HOMOL: '[1]TABLA DE NOMBRES'!#REF!

Sheet Hoja de CIERRE
B1: HOJA DE CIERRE PROPUESTA
I3: IMA Servicios Industriales Argentina S.A.
B5: NOMBRE PROPUESTA: | I5: PAMPA SERVICIOS MENORES CIVILES
B7: NOMBRE CLIENTE: | I7: PAMPA | AA7: FECHA: | AD7: 46199
B9: REFERENCIA CLIENTE: | I9: Nº LICITACIÓN: SIN | AA9: C.I.
B11: SOLICITADO POR: | U11: CARGO:
B13: COTIZADO POR: | I13: SHM | U13: Vendedor: | X13: SHM
B14: REVISADO POR:
B16: OFERTA Nº: | I16: PRE-ARG-1340
B18: OBJETIVO Y ALCANCE:
B20: SERVICIO PAMPA
B25: GARANTIAS:
J26: SI | L26: NO | N26: DESCRIPCION
B27: SERIEDAD DE LA OFERTA
B28: FIEL CUMPLIMIENTO
B29: RETENCIONES | J29: X | N29: RETENCIÓN DE IVA, IIGG E IIBB
B31: MULTAS:
J32: SI | L32: NO | N32: DESCRIPCION
B33: POR PLAZO DE HITOS | J33: X
B34: PERSONAL | J34: X
B35: EQUIPOS | J35: X
B36: MEDIO AMBIENTE | J36: X
B38: SEGUROS:
J39: SI | L39: NO | N39: DESCRIPCION
B40: ACCIDENTES TRABAJO Y EP | J40: X | N40: ART
B41: VEHICULOS | J41: X | N41: SEGURO
B42: RESPONSABILIDAD CIVIL | J42: X | N42: SEGURO
B43: ACCIDENTES PERSONALES
AD44: AÑOS
B45: DURACION DEL CONTRATO: | N45: 2 AÑOS | AD45: 2
B47: COMPETENCIA:
B54: TIPO DE CONTRATO: | N54: VALOR POR HH
B56: MONEDA Y REAJUSTABILIDAD: | N56: PESOS ARGENTINOS
B58: FORMA DE PAGO: | N58: 30 DIAS FECHA FACTURA
B60: PROGRAMA DE CONTROL DE RIESGOS:
B62: PLAN DE ASEGURAMIENTO DE CALIDAD:
B65: TOTAL COSTO DIRECTOS DE EXPLOTACIÓN + IMP. DIRECTOS | X65: =+'Sintesis Economica'!G18+'Sintesis Economica'!G20 -> 39391444 | AF65: MES
B66: MARGEN BRUTO (RESULTADO OPERACIONAL) | U66: =+X66/X67 -> 0.13742394 | X66: =+X67-X65 -> 6275768.1 | AF66: MES | AH66: =+X66/X65 -> 0.15931805 | AI66: MARGEN IMA
B67: PRECIO DE VENTA (sin IVA) | X67: =+'Sintesis Economica'!G24 -> 45667212 | AF67: MES
B69: FIRMAS COMITE DE CIERRE:

Sheet Sintesis Economica
B1: SINTESIS DE PRESUPUESTO DE VENTA
B2: CLIENTE: | C2: =+'Hoja de CIERRE'!I7 -> PAMPA | I2: Cotizó: | J2: =+'Hoja de CIERRE'!I13 -> SHM
B3: SERVICIO PROYECTO : | C3: =+'Hoja de CIERRE'!I5 -> PAMPA SERVICIOS MENORES CIVILES | I3: Vendió: | J3: =+'Hoja de CIERRE'!X13 -> SHM
I4: Revisó: | J4: =+'Hoja de CIERRE'!I14 -> 0
B5: PLIEGO / E.T.P.: | C5: =+'Hoja de CIERRE'!I9 -> Nº LICITACIÓN: SIN | I5: Fecha: | J5: =+'Hoja de CIERRE'!AD7 -> 46199
B6: OFERTA N°: | C6: =+'Hoja de CIERRE'!I16 -> PRE-ARG-1340 | I6: Revisión | J6: 0
C10: COSTOS | E10: TOTAL HH | F10: TOTAL Ho | G10: VALOR MES | H10: VALOR AÑO | I10: VALOR CONTRATO | N10: CONCEPTOS | O10: PONDERACION PORCENTUAL | P10: INDICES DE ACTULIZACION
C11: 1 | D11: MANO DE OBRA | E11: ='1 MANO DE OBRA'!L44 -> 1623 | F11: =+E11/191 -> 8.4973822 | G11: ='Presupuesto Interno'!E11 -> 27400066 | H11: =+G11*12 -> 3.288008e+08 | I11: =+H11*'Hoja de CIERRE'!$AD$45 -> 6.5760159e+08 | N11: MANO DE OBRA | O11: ='Presupuesto de VENTA'!J13 -> 0.72712444 | P11: Escala Salarial U.O.M. Oct-09 | R11: =+'Hoja de CIERRE'!U66*50% -> 0.068711968 | S11: MARGEN A MANO DE OBRA
C12: 2 | D12: SUMINISTRO DE MATERIALES | G12: ='Presupuesto Interno'!E19 -> 0 | H12: =+G12*12 -> 0 | I12: =+H12*'Hoja de CIERRE'!$AD$45 -> 0 | N12: MATERIALES | O12: 0 | P12: -------
C13: 3 | D13: SUMINISTRO DE INSUMOS | G13: ='Presupuesto Interno'!E25 -> 2787372.8 | H13: =+G13*12 -> 33448474 | I13: =+H13*'Hoja de CIERRE'!$AD$45 -> 66896948 | N13: INSUMOS CONSUMIBLES + EPP | O13: ='Presupuesto de VENTA'!J25 -> 0.064249086 | P13: IPIM - NG Oct-09
C14: 4 | D14: SUBCONTRATACIONES | G14: ='Presupuesto Interno'!E33 -> 100000 | H14: =+G14*12 -> 1200000 | I14: =+H14*'Hoja de CIERRE'!$AD$45 -> 2400000 | N14: COMBUSTIBLES | O14: ='Presupuesto de VENTA'!J33 -> 0.0023050051 | P14: Precio Gas-Oil Oct-09
C15: 5 | D15: AMORTIZACIONES | G15: ='Presupuesto Interno'!E40 -> 3906741.8 | H15: =+G15*12 -> 46880901 | I15: =+H15*'Hoja de CIERRE'!$AD$45 -> 93761802 | N15: AMORTIZACIONES | O15: ='Presupuesto de VENTA'!J40 -> 0.090050597 | P15: Dólar Estadounidense 3,80 $/u$s
C16: 6 | D16: GASTOS GENERALES DE OPERACIÓN (DIRECTOS) | G16: ='Presupuesto Interno'!E48 -> 2137560 | H16: =+G16*12 -> 25650720 | I16: =+H16*'Hoja de CIERRE'!$AD$45 -> 51301440 | N16: SUBCONTRATACIONES + GTOS GRALES | O16: =1-SUM(O11:O15) -> 0.11627087 | P16: IPIM - NG Oct-09
D18: TOTAL COSTOS DIRECTOS DE EXPLOTACIÓN | G18: =SUM(G11:G16) -> 36331741 | H18: =SUM(H11:H16) -> 4.3598089e+08 | I18: =SUM(I11:I16) -> 8.7196178e+08 | O18: =+SUM(O11:O16) -> 1
D20: IMPUESTOS DIRECTOS DE FACTURACIÓN ====>>> | G20: ='Presupuesto de VENTA'!G7 -> 3059703.2 | H20: =+G20*12 -> 36716439 | I20: =+H20*'Hoja de CIERRE'!$AD$45 -> 73432877
D22: MARGEN BRUTO / UTILIDAD BRUTA | E22: =+G22/G24 -> 0.13742394 | G22: =+G24-G18-G20 -> 6275768.1 | H22: =+G22*12 -> 75309217 | I22: =+H22*'Hoja de CIERRE'!$AD$45 -> 1.5061843e+08
C24: PRECIO DE VENTA TOTAL SIN IVA | E24: (Costo + Impuestos + Utilidad) | G24: ='Presupuesto de VENTA'!H7 -> 45667212 | H24: =+G24*12 -> 5.4800655e+08 | I24: =+H24*'Hoja de CIERRE'!$AD$45 -> 1.0960131e+09
C26: I.V.A. | E26: 0.21 | G26: =G24*E26 -> 9590114.6 | H26: =+G26*12 -> 1.1508138e+08 | I26: =+H26*'Hoja de CIERRE'!$AD$45 -> 2.3016275e+08
C28: PRECIO DE VENTA TOTAL CON I.V.A. | G28: =+G24+G26 -> 55257327 | H28: =+H24+H26 -> 6.6308792e+08 | I28: =+I24+I26 -> 1.3261758e+09
C31: VENTA NETA ( Despues de IVA e Impuestos Directos de Facturación) | G31: =+G28-G26-G20 -> 42607509 | H31: =+H28-H26-H20 -> 5.1129011e+08 | I31: =+I28-I26-I20 -> 1.0225802e+09
C33: GASTOS GENERALES DE ESTRUCTURA | E33: 0 | G33: =+G31*$E$33 -> 0 | H33: =+H31*$E$33 -> 0 | I33: =+I31*$E$33 -> 0
C35: UTILIDAD NETA OPERATIVA MENSUAL | F35: =+G35/G31 -> 0.14729254 | G35: =+G31-G18-G33 -> 6275768.1 | H35: =+H31-H18-H33 -> 75309217 | I35: =+I31-I18-I33 -> 1.5061843e+08
C36: UTILIDAD NETA OPERATIVA TOTAL (Acumulada) - Estimación | G36: =+I35 -> 1.5061843e+08
C38: (INVERSIÓN / FACTURACIÓN) ---- INVERSIÓN | F38: =+G38/$G$24 -> 3.1641958 | G38: =+'5 AMORTIZACIÓN'!F89 -> 144500000
C39: R.O.I. (RENTABILIDAD SOBRE LA INVERSIÓN) | G39: =((G36/G38)/('Hoja de CIERRE'!$AD$45)) -> 0.52117105
B42: ANALISIS COMPARATIVO DE ITMS UNITARIOS
E44: COSTO MO | F44: PRECIO VENTA | G44: UTILIDAD NETA OPERATIVA | J44: MAKE-UP
B46: POR HOMBRE (Ho) | E46: =+G11/F11 -> 3224530.3 | F46: =+G24/F11 -> 5374268.4 | G46: =+G35/F11 -> 738553.11 | J46: =+F46/E46 -> 1.6666825
B48: POR HORA HOMRE (HH) | E48: =+G11/E11 -> 16882.358 | F48: =+G24/E11 -> 28137.531 | G48: =+G35/E11 -> 3866.7702 | J48: =+F48/E48 -> 1.6666825
B52: AUTORIZADO POR:
B54: FUNCIÓN/CARGO: | F54: FIRMA:
B57: COMENTARIOS:

Sheet Presupuesto de VENTA
B1: PRESUPUESTO INTERNO DE VENTA
C2: CLIENTE: | D2: =+'Sintesis Economica'!C2 -> PAMPA | I2: J. de PROYECTO: | J2: =+'Sintesis Economica'!J2 -> SHM
C3: OBRA : | D3: =+'Sintesis Economica'!C3 -> PAMPA SERVICIOS MENORES CIVILES | I3: Elaboró: | J3: =+'Sintesis Economica'!J3 -> SHM
C4: PLIEGO / E.T.P.: | D4: =+'Sintesis Economica'!C5 -> Nº LICITACIÓN: SIN | I4: Revisó: | J4: =+'Sintesis Economica'!J4 -> 0
C5: OFERTA N°: | D5: =+'Sintesis Economica'!C6 -> PRE-ARG-1340 | I5: Fecha: | J5: =+'Sintesis Economica'!J5 -> 46199
H6: =6*H7 -> 2.7400327e+08
B7: MARGEN BRUTO FINAL | D7: PRECIO DE VENTA CON IMPUESTOS | F7: =+(5+1.2+0.5)% -> 0.067 | G7: =-H11+H11/(1-F7) -> 3059703.2 | H7: =+H11+G7 -> 45667212 | I7: =+H7/$E$9 -> 34887.099 | J7: =H7*12 -> 5.4800655e+08 | K7: =I7/28000 -> 1.2459678
H8: =H7-H41-H74 -> 42504941 | I8: =H8/E9 -> 32471.307
B9: =+(H7-F11-G7)/H7 -> 0.13742394 | D9: DOTACIÓN | E9: ='Presupuesto Interno'!D7 -> 1309 | F9: COSTOS | G9: MARGEN BRUTO (sin impuestos) | H9: PRECIO VENTA (sin impuestos) | I9: PRECIO VENTA POR H-H | J9: % DE DISTRIBUCIÓN | L9: =(H7-G7)/F11-1 -> 0.17273513 | N9: MARGEN BRUTO TRADICIONAL | O9: factor he | Q9: 2 OP
O10: Bruto | P10: General | Q10: Total
B11: ITEMS | F11: =F13+F19+F25+F33+F40+F48 -> 36331741 | G11: =+(H11-F11)/H11 -> 0.14729254 | H11: =+H13+H19+H25+H33+H40+H48 -> 42607509 | I11: =H11/$E$9 -> 32549.663 | J11: =+SUM(J13:J48) -> 8900.212 | N11: ='1 MANO DE OBRA'!B17 -> MEDIO OFICIAL | O11: ='1 MANO DE OBRA'!F17 -> 177.06477 | P11: =$L$4 -> 0 | Q11: =O11+P11 -> 177.06477 | R11: =AVERAGE(Q11:Q12) -> 8700.0774
N12: ='1 MANO DE OBRA'!B18 -> OFICIAL | O12: ='1 MANO DE OBRA'!F18 -> 17223.09 | P12: =$L$4 -> 0 | Q12: =O12+P12 -> 17223.09
B13: 1- MANO DE OBRA | F13: =SUM(F14:F17) -> 27400066 | G13: =+(H13-F13)/H13 -> 0.17483962 | H13: =SUM(H14:H17) -> 33205746 | I13: =H13/$E$9 -> 25367.262 | J13: =+H13/$H$7 -> 0.72712444 | K13: 0.76586865 | N13: ='1 MANO DE OBRA'!B19 -> OFICIAL ESPACIALIZADO | O13: ='1 MANO DE OBRA'!F19 -> 18905.25 | P13: =$L$4 -> 0 | Q13: =(O13+P13)*1.1 -> 20795.775 | R13: =Q13 -> 20795.775 | S13: =R13/R11 -> 2.3902977
D14: =+'Presupuesto Interno'!C12 -> 1.1 Directa (Personal de Convenio) | F14: =+'Presupuesto Interno'!E12 -> 22545025 | G14: 0.18 | H14: =+F14/(1-G14) -> 27493933
D15: =+'Presupuesto Interno'!C13 -> 1.2 Indirecta (Personal fuera de Convenio) | F15: =+'Presupuesto Interno'!E13 -> 4855041.6 | G15: 0.15 | H15: =+F15/(1-G15) -> 5711813.6 | J15: =F15/$E$9 -> 3708.9699
D16: =+'Presupuesto Interno'!C14 -> 1.3 Cobertura de licencias (Horas-Hombre) | F16: =+'Presupuesto Interno'!E14 -> 0 | G16: 0.04 | H16: =+F16/(1-G16) -> 0
D17: =+'Presupuesto Interno'!C15 -> 1.4 Mano de Obra Eventual | F17: =+'Presupuesto Interno'!E15 -> 0 | G17: 0.04 | H17: =+F17/(1-G17) -> 0
B19: 2- SUMINISTRO DE MATERIALES | F19: =SUM(F20:F23) -> 0 | G19: =+(H19-F19)/H19 -> #DIV/0! | H19: =SUM(H20:H23) -> 0 | I19: =H19/$E$9 -> 0 | J19: =+H19/$H$7 -> 0 | K19: 0
D20: =+'Presupuesto Interno'!C20 -> 2.1 Materiales Mecánicos | F20: =+'Presupuesto Interno'!E20 -> 0 | G20: 0 | H20: =+F20/(1-G20) -> 0
D21: =+'Presupuesto Interno'!C21 -> 2.2 Materiales Eléctricos | F21: =+'Presupuesto Interno'!E21 -> 0 | G21: 0 | H21: =+F21/(1-G21) -> 0
D22: =+'Presupuesto Interno'!C22 -> 2.3 Materiales de Automación e Informática | F22: =+'Presupuesto Interno'!E22 -> 0 | G22: 0 | H22: =+F22/(1-G22) -> 0
D23: =+'Presupuesto Interno'!C23 -> 2.4 Materiales Diversos | F23: =+'Presupuesto Interno'!E23 -> 0 | G23: 0 | H23: =+F23/(1-G23) -> 0
B25: 3- SUMINISTRO DE INSUMOS | F25: =SUM(F26:F31) -> 2787372.8 | G25: =(H25-F25)/H25 -> 0.05 | H25: =SUM(H26:H31) -> 2934076.7 | I25: =H25/$E$9 -> 2241.4642 | J25: =+H25/$H$7 -> 0.064249086 | K25: 0.033793843
D26: =+'Presupuesto Interno'!C26 -> 3.1 Insumos consumibles (Insumos de Mantenimto y operación) | F26: =+'Presupuesto Interno'!E26 -> 523600 | G26: 0.05 | H26: =+F26/(1-G26) -> 551157.89 | J26: =F26/$E$9 -> 400
D27: =+'Presupuesto Interno'!C27 -> 3.2 Combustibles, filtros y lubricantes de Rodados y Máquinas | F27: =+'Presupuesto Interno'!E27 -> 1400000 | G27: 0.05 | H27: =+F27/(1-G27) -> 1473684.2 | J27: =F27/$E$9 -> 1069.5187
D28: =+'Presupuesto Interno'!C28 -> 3.3 Insumos informáticos y de Oficina | F28: =+'Presupuesto Interno'!E28 -> 15000 | G28: 0.05 | H28: =+F28/(1-G28) -> 15789.474 | J28: =F28/$E$9 -> 11.459129
D29: =+'Presupuesto Interno'!C29 -> 3.4 Insumos de Limpieza y Cafetería | F29: =+'Presupuesto Interno'!E29 -> 15000 | G29: 0.05 | H29: =+F29/(1-G29) -> 15789.474 | J29: =F29/$E$9 -> 11.459129
D30: =+'Presupuesto Interno'!C30 -> 3.5 Elementos de Protección Personal y de Seguridad Especiales | F30: =+'Presupuesto Interno'!E30 -> 833772.83 | G30: 0.05 | H30: =+F30/(1-G30) -> 877655.61 | J30: =F30/$E$9 -> 636.95404
D31: =+'Presupuesto Interno'!C31 -> 3.6 Insumos Diversos | F31: =+'Presupuesto Interno'!E31 -> 0 | G31: 0.05 | H31: =+F31/(1-G31) -> 0
B33: 4- SUBCONTRATACIONES | F33: =SUM(F34:F38) -> 100000 | G33: =+(H33-F33)/H33 -> 0.05 | H33: =SUM(H34:H38) -> 105263.16 | I33: =H33/$E$9 -> 80.414941 | J33: =+H33/$H$7 -> 0.0023050051 | K33: 0.0093456854
D34: =+'Presupuesto Interno'!C34 -> 4.1 Honorarios Profesionales | F34: =+'Presupuesto Interno'!E34 -> 100000 | G34: 0.05 | H34: =+F34/(1-G34) -> 105263.16 | J34: =F34/$E$9 -> 76.394194
D35: =+'Presupuesto Interno'!C35 -> 4.2 Servicios Técnicos Especializados | F35: =+'Presupuesto Interno'!E35 -> 0 | G35: 0.05 | H35: =+F35/(1-G35) -> 0 | J35: =F35/$E$9 -> 0
D36: =+'Presupuesto Interno'!C36 -> 4.3 Transportes, Fletes, Carga y descarga | F36: =+'Presupuesto Interno'!E36 -> 0 | G36: 0.05 | H36: =+F36/(1-G36) -> 0 | J36: =F36/$E$9 -> 0
D37: =+'Presupuesto Interno'!C37 -> 4.4 Trabajos ejecutados por Terceros | F37: =+'Presupuesto Interno'!E37 -> 0 | G37: 0.05 | H37: =+F37/(1-G37) -> 0 | J37: =F37/$E$9 -> 0
D38: =+'Presupuesto Interno'!C38 -> 4.5 Servicio Varios / Otros | F38: =+'Presupuesto Interno'!E38 -> 0 | G38: 0.05 | H38: =+F38/(1-G38) -> 0 | J38: =F38/$E$9 -> 0
B40: 5- AMORTIZACIONES | F40: =SUM(F41:F46) -> 3906741.8 | G40: =+(H40-F40)/H40 -> 0.05 | H40: =SUM(H41:H46) -> 4112359.7 | I40: =H40/$E$9 -> 3141.6041 | J40: =+H40/$H$7 -> 0.090050597 | K40: 0.065203183
D41: =+'Presupuesto Interno'!C41 -> 5.1 Amortizacion de Rodados | F41: =+'Presupuesto Interno'!E41 -> 2804158 | G41: 0.05 | H41: =+F41/(1-G41) -> 2951745.3 | J41: =F41/$E$9 -> 2142.2139
D42: =+'Presupuesto Interno'!C42 -> 5.2 Amortización de Muebles y Útiles | F42: =+'Presupuesto Interno'!E42 -> 141839.39 | G42: 0.05 | H42: =+F42/(1-G42) -> 149304.63 | J42: =F42/$E$9 -> 108.35706 | K42: =F42/H7 -> 0.003105935
D43: =+'Presupuesto Interno'!C43 -> 5.3 Amortización de Instalaciones y adecuación de locales | F43: =+'Presupuesto Interno'!E43 -> 0 | G43: 0.05 | H43: =+F43/(1-G43) -> 0 | J43: =F43/$E$9 -> 0
D44: =+'Presupuesto Interno'!C44 -> 5.4 Amortización de Medios Informáticos y de Comunicación | F44: =+'Presupuesto Interno'!E44 -> 156931.41 | G44: 0.05 | H44: =+F44/(1-G44) -> 165190.96 | J44: =F44/$E$9 -> 119.88649
...

Sheet Presupuesto Interno
A1: PRESUPUESTO INTERNO DE COSTOS Y GASTOS
B2: CLIENTE: | C2: =+'Sintesis Economica'!C2 -> PAMPA | F2: J. de PROYECTO: | G2: =+'Sintesis Economica'!J2 -> SHM
B3: OBRA : | C3: =+'Sintesis Economica'!C3 -> PAMPA SERVICIOS MENORES CIVILES | F3: Elaboró: | G3: =+'Sintesis Economica'!J3 -> SHM
B4: PLIEGO / E.T.P.: | C4: =+'Sintesis Economica'!C5 -> Nº LICITACIÓN: SIN | F4: Revisó: | G4: =+'Sintesis Economica'!J4 -> 0
B5: OFERTA N°: | C5: =+'Sintesis Economica'!C6 -> PRE-ARG-1340 | F5: Fecha: | G5: =+'Sintesis Economica'!J5 -> 46199 | J5: =800*41 -> 32800
A7: DOTACIÓN | D7: =SUM('1 MANO DE OBRA'!C15:C20) -> 1309 | E7: COSTOS TOTALES | F7: COSTOS UNITARIOS | G7: % DE DISTRIBUCIÓN
A9: ITEMS | E9: =E11+E19+E25+E33+E40+E48 -> 36331741 | F9: =E9/$D$7 -> 27755.341 | G9: =+SUM(G11:G48) -> 1
A11: 1- MANO DE OBRA | E11: =SUM(E12:E15) -> 27400066 | F11: =E11/$D$7 -> 20932.06 | G11: =E11/$E$9 -> 0.75416332 | I11: =+(I12-I13)*0 -> 0 | J11: COSTO NO CUBIERTO
C12: 1.1 Directa (Personal de Convenio) | E12: ='1 MANO DE OBRA'!L24 -> 22545025 | I12: =2700*2.1/(6*187) -> 5.0534759 | J12: COSTO SUPERVISOR ADICIONALES
C13: 1.2 Indirecta (Personal fuera de Convenio) | E13: ='1 MANO DE OBRA'!L36 -> 4855041.6 | I13: =+E13/D7*15% -> 556.34548 | J13: COSTO MO SUPERVISION PONDERADA
B14: 1 | C14: 1.3 Cobertura de licencias (Horas-Hombre) | E14: =+D14*$E$17 -> 0
C15: 1.4 Mano de Obra Eventual
C17: COSTO HORA HOMBRE DE REFERENCIA P/COBERTURA DE LICENCIAS | E17: 25
A19: 2- SUMINISTRO DE MATERIALES | E19: =SUM(E20:E23) -> 0 | F19: =E19/$D$7 -> 0 | G19: =E19/$E$9 -> 0
C20: 2.1 Materiales Mecánicos | E20: ='2 SUMINISTRO DE MATERIALES'!G20 -> 0
C21: 2.2 Materiales Eléctricos | E21: ='2 SUMINISTRO DE MATERIALES'!G33 -> 0
C22: 2.3 Materiales de Automación e Informática | E22: ='2 SUMINISTRO DE MATERIALES'!G39 -> 0
C23: 2.4 Materiales Diversos | E23: ='2 SUMINISTRO DE MATERIALES'!G51 -> 0
A25: 3- SUMINISTRO DE INSUMOS | E25: =SUM(E26:E31) -> 2787372.8 | F25: =E25/$D$7 -> 2129.391 | G25: =E25/$E$9 -> 0.076720046
C26: 3.1 Insumos consumibles (Insumos de Mantenimto y operación) | E26: ='3 SUMINISTRO DE INSUMOS'!F39 -> 523600 | I26: =+(E26+E30)/D7 -> 1036.954 | J26: COSTO DE INSUMOS+EPP
C27: 3.2 Combustibles, filtros y lubricantes de Rodados y Máquinas | E27: ='3 SUMINISTRO DE INSUMOS'!F54 -> 1400000
C28: 3.3 Insumos informáticos y de Oficina | E28: ='3 SUMINISTRO DE INSUMOS'!F61 -> 15000
C29: 3.4 Insumos de Limpieza y Cafetería | E29: ='3 SUMINISTRO DE INSUMOS'!F68 -> 15000
C30: 3.5 Elementos de Protección Personal y de Seguridad Especiales | E30: ='3 SUMINISTRO DE INSUMOS'!F87 -> 833772.83
C31: 3.6 Insumos Diversos | E31: ='3 SUMINISTRO DE INSUMOS'!F96 -> 0
A33: 4- SUBCONTRATACIONES | E33: =SUM(E34:E38) -> 100000 | F33: =E33/$D$7 -> 76.394194 | G33: =E33/$E$9 -> 0.0027524142
C34: 4.1 Honorarios Profesionales | E34: =+'4 SUBCONTRATACIONES'!F26 -> 100000
C35: 4.2 Servicios Técnicos Especializados | E35: =+'4 SUBCONTRATACIONES'!F47 -> 0
C36: 4.3 Transportes, Fletes, Carga y descarga | E36: =+'4 SUBCONTRATACIONES'!F68 -> 0
C37: 4.4 Trabajos ejecutados por Terceros | E37: =+'4 SUBCONTRATACIONES'!F89 -> 0
C38: 4.5 Servicio Varios / Otros | E38: =+'4 SUBCONTRATACIONES'!F110 -> 0
A40: 5- AMORTIZACIONES | E40: =SUM(E41:E46) -> 3906741.8 | F40: =E40/$D$7 -> 2984.5239 | G40: =E40/$E$9 -> 0.10752971
C41: 5.1 Amortizacion de Rodados | E41: =+'5 AMORTIZACIÓN'!K10 -> 2804158
C42: 5.2 Amortización de Muebles y Útiles | E42: =+'5 AMORTIZACIÓN'!K23 -> 141839.39
C43: 5.3 Amortización de Instalaciones y adecuación de locales | E43: =+'5 AMORTIZACIÓN'!K36 -> 0
C44: 5.4 Amortización de Medios Informáticos y de Comunicación | E44: =+'5 AMORTIZACIÓN'!K49 -> 156931.41
C45: 5.5 Amortización de Máquinas y Herramientas | E45: =+'5 AMORTIZACIÓN'!K62 -> 803812.91 | I45: =+E45/D7*20% -> 122.81328 | J45: COSTO AMORT. HTAS PONDERADO
C46: 5.6 Amortización de Gastos de Implementación | E46: =+'5 AMORTIZACIÓN'!K75 -> 0
A48: 6- GASTOS GENERALES | E48: =E50+E55+E61+E67+E73+E80+E88 -> 2137560 | F48: =E48/$D$7 -> 1632.9717 | G48: =E48/$E$9 -> 0.058834505
B50: 6.1 Servicios | E50: =SUM(E51:E53) -> 250060 | J50: TELEFONIA MOVIL NEXTEL
...

Sheet 1 MANO DE OBRA
C1: 1 - MANO DE OBRA
B3: CLIENTE: | C3: ='Sintesis Economica'!C2 -> PAMPA | K3: J. de PROYECTO: | L3: ='Sintesis Economica'!J2 -> SHM
B4: OBRA : | C4: ='Sintesis Economica'!C3 -> PAMPA SERVICIOS MENORES CIVILES | K4: Elaboró: | L4: ='Sintesis Economica'!J3 -> SHM
B5: PLIEGO / E.T.P.Nº: | C5: ='Sintesis Economica'!C5 -> Nº LICITACIÓN: SIN | K5: Revisó: | L5: ='Sintesis Economica'!J4 -> 0
B6: OFERTA N°: | C6: ='Sintesis Economica'!C6 -> PRE-ARG-1340 | K6: Fecha: | L6: ='Sintesis Economica'!J5 -> 46199
C8: COEF. POR HORAS EXTRAS | G8: 1.5 | H8: 2
D9: 0 | E9: 0
B10: MANO DE OBRA
B11: MANO DE OBRA DIRECTA (UOM + ASMRA) | C11: CANTIDAD HHN | D11: CANTIDAD HH 50% | E11: CANTIDAD HH 100% | F11: Costo Unit. HHN | G11: Costo Unit. HH 50% | H11: Costo Unit. HH 100% | I11: Costo Horas Normales | J11: Costo Horas 50% | K11: Costo Horas 100% | L11: Costo total
G12: =+F12*$G$8 -> 0 | H12: =+F12*$H$8 -> 0 | I12: =+C12*F12 -> 0 | J12: =+D12*G12 -> 0 | K12: =+E12*H12 -> 0 | L12: =I12+J12+K12 -> 0
G13: =+F13*$G$8 -> 0 | H13: =+F13*$H$8 -> 0 | I13: =+C13*F13 -> 0 | J13: =+D13*G13 -> 0 | K13: =+E13*H13 -> 0 | L13: =I13+J13+K13 -> 0
D14: =+C14*$D$9 -> 0 | E14: =+C14*$E$9 -> 0 | F14: =+'COSTO UNIT.MO_UOM_CAT-GRAL'!P84 -> 166.36958 | G14: =+F14*$G$8 -> 249.55437 | H14: =+F14*$H$8 -> 332.73916 | I14: =+C14*F14 -> 0 | J14: =+D14*G14 -> 0 | K14: =+E14*H14 -> 0 | L14: =I14+J14+K14 -> 0
D15: =+C15*$D$9 -> 0 | E15: =+C15*$E$9 -> 0 | F15: =+'COSTO UNIT.MO_UOM_CAT-GRAL'!N84 -> 177.06477 | G15: =+F15*$G$8 -> 265.59715 | H15: =+F15*$H$8 -> 354.12953 | I15: =+C15*F15 -> 0 | J15: =+D15*G15 -> 0 | K15: =+E15*H15 -> 0 | L15: =I15+J15+K15 -> 0
D16: =+C16*$D$9 -> 0 | E16: =+C16*$E$9 -> 0 | F16: =+'COSTO UNIT.MO_UOM_CAT-GRAL'!L84 -> 177.06477 | G16: =+F16*$G$8 -> 265.59715 | H16: =+F16*$H$8 -> 354.12953 | I16: =+C16*F16 -> 0 | J16: =+D16*G16 -> 0 | K16: =+E16*H16 -> 0 | L16: =I16+J16+K16 -> 0
B17: ='COSTO UNIT.MO_UOM_CAT-GRAL'!I13 -> MEDIO OFICIAL | D17: 0 | E17: =+C17*$E$9 -> 0 | F17: =+'COSTO UNIT.MO_UOM_CAT-GRAL'!J84 -> 177.06477 | G17: =+F17*$G$8 -> 265.59715 | H17: =+F17*$H$8 -> 354.12953 | I17: =+C17*F17 -> 0 | J17: =+D17*G17 -> 0 | K17: =+E17*H17 -> 0 | L17: =I17+J17+K17 -> 0
B18: ='COSTO UNIT.MO_UOM_CAT-GRAL'!G13 -> OFICIAL | C18: =7*187 -> 1309 | D18: 0 | E18: =+C18*$E$9 -> 0 | F18: =+'COSTO UNIT.MO_UOM_CAT-GRAL'!H84 -> 17223.09 | G18: =+F18*$G$8 -> 25834.635 | H18: =+F18*$H$8 -> 34446.18 | I18: =+C18*F18 -> 22545025 | J18: =+D18*G18 -> 0 | K18: =+E18*H18 -> 0 | L18: =I18+J18+K18 -> 22545025
B19: ='COSTO UNIT.MO_UOM_CAT-GRAL'!E13 -> OFICIAL ESPACIALIZADO | D19: =+C19*$D$9 -> 0 | E19: =+C19*$E$9 -> 0 | F19: =+'COSTO UNIT.MO_UOM_CAT-GRAL'!F84 -> 18905.25 | G19: =+F19*$G$8 -> 28357.875 | H19: =+F19*$H$8 -> 37810.501 | I19: =+C19*F19 -> 0 | J19: =+D19*G19 -> 0 | K19: =+E19*H19 -> 0 | L19: =I19+J19+K19 -> 0
G20: =+F20*$G$8 -> 0 | H20: =+F20*$H$8 -> 0 | I20: =+C20*F20 -> 0 | J20: =+D20*G20 -> 0 | K20: =+E20*H20 -> 0 | L20: =I20+J20+K20 -> 0
G21: =+F21*$G$8 -> 0 | H21: =+F21*$H$8 -> 0 | I21: =+C21*F21 -> 0 | J21: =+D21*G21 -> 0 | K21: =+E21*H21 -> 0 | L21: =I21+J21+K21 -> 0
G22: =+F22*$G$8 -> 0 | H22: =+F22*$H$8 -> 0 | I22: =+C22*F22 -> 0 | J22: =+D22*G22 -> 0 | K22: =+E22*H22 -> 0 | L22: =I22+J22+K22 -> 0
I23: =+C23*F23 -> 0 | J23: =+D23*G23 -> 0 | K23: =+E23*H23 -> 0 | L23: =I23+J23+K23 -> 0
B24: TOTAL ($) MANO DE OBRA DIRECTA | C24: =+SUM(C12:C23) -> 1309 | D24: =+SUM(D12:D23) -> 0 | E24: =+SUM(E12:E23) -> 0 | I24: =SUM(I12:I23) -> 22545025 | J24: =SUM(J12:J23) -> 0 | K24: =SUM(K12:K23) -> 0 | L24: =SUM(L12:L23) -> 22545025 | M24: =+I24/C24 -> 17223.09 | P24: =C24/187 -> 7
B25: MANO DE OBRA INDIRECTA | C25: Cantidad Horas Normal | D25: Cantidad Horas 50% | E25: Cantidad Horas 100% | F25: Costo Unit. HHN | G25: Costo Unit. HH 50% | H25: Costo Unit. HH 100% | I25: Costo Horas Normales | J25: Costo Horas 50% | K25: Costo Horas 100% | L25: Costo total
B26: =+'COSTO MO FC'!B8 -> ADMINITRADOR DE CONTRATO | C26: 0 | D26: =+C26*0% -> 0 | E26: =+C26*0% -> 0 | F26: =+'COSTO MO FC'!AJ8 -> 22344.414 | G26: =+F26*$G$8 -> 33516.621 | H26: =+F26*$H$8 -> 44688.828 | I26: =+C26*F26 -> 0 | J26: =+D26*G26 -> 0 | K26: =+E26*H26 -> 0 | L26: =I26+J26+K26 -> 0
B27: =+'COSTO MO FC'!B9 -> JEFE DE S&SO, MA y CALIDAD | C27: 8 | D27: =+C27*0% -> 0 | E27: =+C27*0% -> 0 | F27: =+'COSTO MO FC'!AJ9 -> 16012.987 | G27: =+F27*$G$8 -> 24019.48 | H27: =+F27*$H$8 -> 32025.974 | I27: =+C27*F27 -> 128103.89 | J27: =+D27*G27 -> 0 | K27: =+E27*H27 -> 0 | L27: =I27+J27+K27 -> 128103.89
B28: =+'COSTO MO FC'!B10 -> TECNICOS SEGURIDAD | C28: 100 | D28: =+C28*0% -> 0 | E28: =+C28*0% -> 0 | F28: =+'COSTO MO FC'!AJ10 -> 15420.397 | G28: =+F28*$G$8 -> 23130.595 | H28: =+F28*$H$8 -> 30840.794 | I28: =+C28*F28 -> 1542039.7 | J28: =+D28*G28 -> 0 | K28: =+E28*H28 -> 0 | L28: =I28+J28+K28 -> 1542039.7
B29: =+'COSTO MO FC'!B11 -> SUPERVISOR | C29: 200 | D29: =+C29*0% -> 0 | E29: =+C29*0% -> 0 | F29: =+'COSTO MO FC'!AJ11 -> 15657.433 | G29: =+F29*$G$8 -> 23486.149 | H29: =+F29*$H$8 -> 31314.866 | I29: =+C29*F29 -> 3131486.6 | J29: =+D29*G29 -> 0 | K29: =+E29*H29 -> 0 | L29: =I29+J29+K29 -> 3131486.6
B30: =+'COSTO MO FC'!B12 -> ADMINISTRATIVO | C30: 6 | D30: =+C30*0% -> 0 | E30: =+C30*0% -> 0 | F30: =+'COSTO MO FC'!AJ12 -> 8901.9075 | G30: =+F30*$G$8 -> 13352.861 | H30: =+F30*$H$8 -> 17803.815 | I30: =+C30*F30 -> 53411.445 | J30: =+D30*G30 -> 0 | K30: =+E30*H30 -> 0 | L30: =I30+J30+K30 -> 53411.445 | N30: =L30/L36 -> 0.011001233
B31: =+'COSTO MO FC'!B13 -> PAÑOLERO | C31: 0 | D31: =+C31*0% -> 0 | E31: =+C31*0% -> 0 | F31: =+'COSTO MO FC'!AJ13 -> 8901.9075 | G31: =+F31*$G$8 -> 13352.861 | H31: =+F31*$H$8 -> 17803.815 | I31: =+C31*F31 -> 0 | J31: =+D31*G31 -> 0 | K31: =+E31*H31 -> 0 | L31: =I31+J31+K31 -> 0
B32: =+'COSTO MO FC'!B14 -> CHOFER | C32: 0 | D32: =+C32*0% -> 0 | E32: =+C32*0% -> 0 | F32: =+'COSTO MO FC'!AJ14 -> 8901.9075 | G32: =+F32*$G$8 -> 13352.861 | H32: =+F32*$H$8 -> 17803.815 | I32: =+C32*F32 -> 0 | J32: =+D32*G32 -> 0 | K32: =+E32*H32 -> 0 | L32: =I32+J32+K32 -> 0
B33: =+'COSTO MO FC'!B15 -> LIMPIEZA | C33: 0 | D33: =+C33*0% -> 0 | E33: =+C33*0% -> 0 | F33: =+'COSTO MO FC'!AJ15 -> 8901.9075 | G33: =+F33*$G$8 -> 13352.861 | H33: =+F33*$H$8 -> 17803.815 | I33: =+C33*F33 -> 0 | L33: =I33+J33+K33 -> 0
G34: =+F34*$G$8 -> 0 | H34: =+F34*$H$8 -> 0 | I34: =+C34*F34 -> 0 | L34: =I34+J34+K34 -> 0
G35: =+F35*$G$8 -> 0 | H35: =+F35*$H$8 -> 0 | I35: =+C35*F35 -> 0 | J35: =+D35*G35 -> 0 | K35: =+E35*H35 -> 0 | L35: =I35+J35+K35 -> 0
B36: TOTAL ($) MANO DE OBRA INDIRECTA | C36: =+SUM(C26:C35) -> 314 | D36: =+SUM(D26:D35) -> 0 | E36: =+SUM(E26:E35) -> 0 | I36: =SUM(I26:I35) -> 4855041.6 | J36: =SUM(J26:J35) -> 0 | K36: =SUM(K26:K35) -> 0 | L36: =SUM(L26:L35) -> 4855041.6
B37: MANO DE OBRA EVENTUAL | C37: Cantidad Horas Normal | D37: Cantidad Horas 50% | E37: Cantidad Horas 100% | F37: Costo Unit. HHN | G37: Costo Unit. HH 50% | H37: Costo Unit. HH 100% | I37: Costo Horas Normales | J37: Costo Horas 50% | K37: Costo Horas 100% | L37: Costo total
G38: =+F38*$G$8 -> 0 | H38: =+F38*$H$8 -> 0 | I38: =+C38*F38 -> 0 | J38: =+D38*G38 -> 0 | K38: =+E38*H38 -> 0 | L38: =I38+J38+K38 -> 0
G39: =+F39*$G$8 -> 0 | H39: =+F39*$H$8 -> 0 | I39: =+C39*F39 -> 0 | J39: =+D39*G39 -> 0 | K39: =+E39*H39 -> 0 | L39: =I39+J39+K39 -> 0
G40: =+F40*$G$8 -> 0 | H40: =+F40*$H$8 -> 0 | I40: =+C40*F40 -> 0 | J40: =+D40*G40 -> 0 | K40: =+E40*H40 -> 0 | L40: =I40+J40+K40 -> 0
G41: =+F41*$G$8 -> 0 | H41: =+F41*$H$8 -> 0 | I41: =+C41*F41 -> 0 | J41: =+D41*G41 -> 0 | K41: =+E41*H41 -> 0 | L41: =I41+J41+K41 -> 0
B42: TOTAL ($) MANO DE OBRA EVENTUAL | C42: =+SUM(C38:C41) -> 0 | D42: =+SUM(D38:D41) -> 0 | E42: =+SUM(E38:E41) -> 0 | I42: =SUM(I38:I41) -> 0 | J42: =SUM(J38:J41) -> 0 | K42: =SUM(K38:K41) -> 0 | L42: =SUM(L38:L41) -> 0
...

Sheet COSTO UNIT.MO_UOM_CAT-GRAL
A1: APERTURA DE COSTOS
A2: MOA U.O.M. - CATEGORIAS GENERALES
A4: TP=25%
A5: Adicional acería=25%
A6: Calorias=10%
A7: Insalubre=3%
D9: vigencia
A10: VALOR DE CATEGORIA | D10: 46174 | E10: =G10*1.1 -> 6273.3 | G10: 5703
B12: =SUM(E16:E22) -> 1407728.5 | E12: ESPECIALIDAD EN HORAS NORMALES
A13: 1) MANO DE OBRA | B13: =B12*0.805 -> 1133221.5 | E13: OFICIAL ESPACIALIZADO | G13: OFICIAL | I13: MEDIO OFICIAL | K13: AYUDANTE | M13: ='1 MANO DE OBRA'!$B15 -> 0 | O13: ='1 MANO DE OBRA'!$B14 -> 0
B14: =B13*1.7 -> 1926476.5 | E14: $/mes | F14: $/H | G14: $/mes | H14: $/H | I14: $/mes | J14: $/H | K14: $/mes | L14: $/H | M14: $/mes | N14: $/H | O14: $/mes | P14: $/H | Q14: $/mes | R14: $/H | S14: $/mes | T14: $/H
A15: Concepto | D15: VALOR - % | E15: Sueldo Bruto | G15: Sueldo Bruto | I15: Sueldo Bruto | K15: Sueldo Bruto | M15: Sueldo Bruto | O15: Sueldo Bruto | Q15: Sueldo Bruto | S15: Sueldo Bruto
A16: ** Sueldo Básico (CATEGORIA) | E16: =E10*187 -> 1173107.1 | G16: =G10*187 -> 1066461 | I16: =I10*187 -> 0 | K16: =+K10*$C$87 -> 0 | M16: =+M10*$C$87 -> 0 | O16: =+O10*$C$87 -> 0 | Q16: =+Q10*$C$87 -> 0 | S16: =+S10*$C$87 -> 0 | T16: =+S16+S20+S21+S22+S25+S29 -> 0
A17: ** vales alimentarios a remunerativos
A18: ** Electromecanico | M18: =$D$18*M16 -> 0 | O18: =$D$18*O16 -> 0
A19: ** Antigüedad | D19: 0 | K19: =K16*$D$19 -> 0 | M19: =M16*$D$19 -> 0 | O19: =O16*$D$19 -> 0 | Q19: =+(Q16+Q17+Q20+Q21+Q22+Q25)*$D$19*$C$19 -> 0 | S19: =+(S16+S17+S20+S21+S22+S25)*$D$19*$C$19 -> 0
A20: ** Presentismo | D20: 0.2 | E20: =D20*E16 -> 234621.42 | G20: =D20*G16 -> 213292.2 | I20: =D20*I16 -> 0 | M20: =M16*$D$20 -> 0 | O20: =O16*$D$20 -> 0 | Q20: =+Q16*20%*$D$20 -> 0 | S20: =$D20*S10 -> 0
A21: ** Adicional ELECTRICIDAD | E21: =E16*D21 -> 0 | G21: =G16*F21 -> 0 | I21: =I16*H21 -> 0 | K21: =K10*20%*$D21*187 -> 0 | S21: =+S16*20%*$D$21 -> 0
A22: ** ADICIONAL ALTURA (10%) | E22: =E16*D22 -> 0 | G22: =G16*D22 -> 0 | I22: =I16*D22 -> 0 | Q22: =+Q16*13%*$D$22 -> 0 | S22: =$D22*9 -> 0
A23: ** Adicional Nocturnas | K23: =K$10*13%*$D23*187 -> 0 | Q23: =+Q17*13%*$D$22 -> 0 | S23: =S16*10%*$D$23 -> 0
A24: ** Adicional Polucion | K24: =K$10*33%*$D24*187 -> 0 | Q24: =+O24 -> 0 | S24: =+Q24 -> 0
A25: ** Adicional Aceria | K25: =$D25*237*187 -> 0 | Q25: =+Q16*20%*$D$25 -> 0 | S25: =+S16*20%*$D$25 -> 0
A26: NR MES | Q26: =SUM(Q16:Q25)*$D$26 -> 0 | S26: =SUM(S16:S25)*$D$26 -> 0
A27: ** Previsión de rotacion he AL 100%+ fc | E27: =(70%*SUM(E16:E26)+55000)/1.4 -> 743149.97 | G27: =(70%*SUM(G16:G26)+55000)/1.4 -> 679162.31
A29: ** ADICIONAL ACINDAR 12% sobre todos los conceptos excepto oras extras | C29: 0.12
B31: Sub - Total | E31: =SUM(E16:E27)+E29 -> 2150878.5 | F31: =E31/$C$87 -> 11502.024 | G31: =SUM(G16:G27)+G29 -> 1958915.5 | H31: =G31/$C$87 -> 10475.484 | I31: =SUM(I16:I27)+I29 -> 0 | J31: =I31/$C$87 -> 0 | K31: =SUM(K16:K27)+K29 -> 0 | L31: =K31/$C$87 -> 0 | M31: =SUM(M16:M27)+M29 -> 0 | N31: =M31/$C$87 -> 0 | O31: =SUM(O16:O27)+O29 -> 0 | P31: =O31/$C$87 -> 0 | Q31: =SUM(Q16:Q27)+Q29 -> 0 | R31: =Q31/$C$87 -> 0 | S31: =SUM(S16:S27)+S29 -> 0 | T31: =S31/$C$87 -> 0
J32: =30.16 -> 30.16
A34: 2) CARGAS SOCIALES DIRECTAS
A35: Concepto | D35: VALOR - %
A36: ** Sistema Integrado de Jubilac. y Pensiones | D36: 0.090718847 | E36: =+$D$36*E31 -> 195125.22 | G36: =+$D$36*G31 -> 177710.56 | I36: =+$D$36*I31 -> 0 | K36: =+$D$36*K31 -> 0 | M36: =+$D$36*M31 -> 0 | O36: =+$D$36*O31 -> 0 | Q36: =+$D$36*Q31 -> 0 | S36: =+$D$36*S31 -> 0
A37: ** Régimen Nacional de Asig. Familiares | D37: 0.0444 | E37: =+$D$37*E31 -> 95499.005 | G37: =+$D$37*G31 -> 86975.849 | I37: =+$D$37*I31 -> 0 | K37: =+$D$37*K31 -> 0 | M37: =+$D$37*M31 -> 0 | O37: =+$D$37*O31 -> 0 | Q37: =+$D$37*Q31 -> 0 | S37: =+$D$37*S31 -> 0
A38: ** Fondo Nacional de Empleo | D38: 0.0089 | E38: =+$D$38*E31 -> 19142.819 | G38: =+$D$38*G31 -> 17434.348 | I38: =+$D$38*I31 -> 0 | K38: =+$D$38*K31 -> 0 | M38: =+$D$38*M31 -> 0 | O38: =+$D$38*O31 -> 0 | Q38: =+$D$38*Q31 -> 0 | S38: =+$D$38*S31 -> 0
A39: ** Ley 19.032 | D39: 0.015 | E39: =+$D$39*E31 -> 32263.177 | G39: =+$D$39*G31 -> 29383.733 | I39: =+$D$39*I31 -> 0 | K39: =+$D$39*K31 -> 0 | M39: =+$D$39*M31 -> 0 | O39: =+$D$39*O31 -> 0 | Q39: =+$D$39*Q31 -> 0 | S39: =+$D$39*S31 -> 0
A40: ** Régimen Nacional de Obras Sociales | D40: 0.055 | E40: =+$D$40*E31 -> 118298.32 | G40: =+$D$40*G31 -> 107740.35 | I40: =+$D$40*I31 -> 0 | K40: =+$D$40*K31 -> 0 | M40: =+$D$40*M31 -> 0 | O40: =+$D$40*O31 -> 0 | Q40: =+$D$40*Q31 -> 0 | S40: =+$D$40*S31 -> 0
A41: ** Fondo Solidario de Redistribución - ANNSSAL | B41: 7368 | D41: 0.005 | E41: =+$D$41*E31 -> 10754.392 | G41: =+$D$41*G31 -> 9794.5776 | I41: =+$D$41*I31 -> 0 | K41: =+$D$41*K31 -> 0 | M41: =+$D$41*M31 -> 0 | O41: =+$D$41*O31 -> 0 | Q41: =+$D$41*Q31 -> 0 | S41: =+$D$41*S31 -> 0
A42: ADICIONAL UOCRA | D42: 0.05 | E42: =$D42*E31 -> 107543.92 | G42: =$D42*G31 -> 97945.776 | I42: =$D42*I31 -> 0 | K42: =$D42*K31 -> 0 | M42: =$D42*M31 -> 0 | O42: =$D42*O31 -> 0 | Q42: =$D42*Q31 -> 0 | S42: =$D42*S31 -> 0
A43: ** Contribución tickets POR CUOTA SINDICAL | D43: 0.025 | E43: =+E17/(1-$D$43)-E17 -> 0 | G43: =+G17/(1-$D$43)-G17 -> 0 | I43: =+I17/(1-$D$43)-I17 -> 0 | K43: =+K17/(1-$D$43)-K17 -> 0 | M43: =+M17/(1-$D$43)-M17 -> 0 | O43: =+O17/(1-$D$43)-O17 -> 0 | Q43: =+Q17/(1-$D$43)-Q17 -> 0 | S43: =+S17/(1-$D$43)-S17 -> 0
B45: Sub - Total | C45: =+SUM(E36:E41)/E31 -> 0.21901885 | D45: =+E45/$E$31 -> 0.26901885 | E45: =+SUM(E36:E43) -> 578626.85 | F45: =E45/$C$87 -> 3094.2612 | G45: =+SUM(G36:G43) -> 526985.19 | H45: =G45/$C$87 -> 2818.1026 | I45: =SUM(I36:I43) -> 0 | J45: =I45/$C$87 -> 0 | K45: =SUM(K36:K43) -> 0 | L45: =K45/$C$87 -> 0 | M45: =SUM(M36:M43) -> 0 | N45: =M45/$C$87 -> 0 | O45: =+SUM(O36:O43) -> 0 | P45: =O45/$C$87 -> 0 | Q45: =SUM(Q36:Q43) -> 0 | R45: =Q45/$C$87 -> 0 | S45: =SUM(S36:S43) -> 0 | T45: =S45/$C$87 -> 0
A47: 3) CARGAS SOCIALES INDIRECTAS
A48: Concepto | D48: VALOR - %
...

Sheet COSTO MO FC
B2: APERTURA DE COSTOS
B6: Categoria | C6: BASICO/Incremento | D6: DED.FUNCIONAL | E6: SUELDO BASICO TOTAL (FIJO + PRIMAS) | G6: Antigüedad | H6: SAC | I6: Vacaciones | J6: Bonif. Vacac. | K6: Sub- Total | L6: Cargas | M6: Diferencia Medicina Pre-paga | N6: ART | O6: Vales Alimentarios | P6: Vales Alimentarios SAC | Q6: Cargas Vales Alimentarios | R6: Costo Emisión Ticket | S6: Seg. Oblig. | T6: Transporte | U6: Comedor | V6: Servicio Med. | W6: Ropa+Reposición | X6: Atención al personal | Y6: Costos acreditación Bancaria | Z6: ART Fijo | AA6: Exam. Preing. | AB6: Homolog. Examen | AC6: Aporte Sindical | AD6: Previsión Recategorización | AE6: Previsión Ausentismo | AF6: Previsión Capacitación | AG6: Provision Despido | AH6: Decreto/Adicional | AI6: TOTAL COSTO MES | AJ6: TOTAL COSTO HH | AL6: SALARIO NETO ANTES DE IIGG | AM6: VALES ALIMENTARIOS | AN6: SALARIO VARIABLE | AO6: SALARIO DE BOLSILLO (LIQUIDO) | AQ6: COEFICIENTE (COSTO/BOLSILLO)
G7: 0 | I7: 14 | J7: 0 | L7: 0.22 | N7: 0.042 | O7: 0 | Q7: 0.14 | R7: 0.04 | S7: 1.3 | T7: 0 | U7: 0 | V7: 0 | W7: =((400+400*10%)/12)*0 -> 0 | X7: 5500 | Y7: 0 | Z7: 0.6 | AA7: 5500 | AB7: 0 | AC7: 0 | AD7: 0 | AE7: 0.05 | AF7: 0.02 | AG7: 0.0833 | AH7: 0 | AJ7: 200
B8: ADMINITRADOR DE CONTRATO | C8: =599000*1.4*2.6*1.2 -> 2616432 | D8: 1000 | E8: =+C8+D8 -> 2617432 | G8: =+((C8+D8)*$G$7) -> 0 | H8: =(C8+D8+G8)/12 -> 218119.33 | I8: =((SUM(C8:G8)/25)*$I$7)/12 -> 244293.65 | J8: =((C8/191)*$J$7)/12 -> 0 | K8: =+E8+SUM(G8:J8) -> 3079845 | L8: =K8*$L$7 -> 677565.9 | N8: =K8*$N$7 -> 129353.49 | O8: =(C8)*$O$7 -> 0 | P8: =O8/12 -> 0 | Q8: =(O8+P8)*$Q$7 -> 0 | R8: =(O8+P8)*$R$7 -> 0 | S8: =+$S$7 -> 1.3 | U8: =+$U$7 -> 0 | V8: =+$V$7 -> 0 | W8: =+$W$7 -> 0 | X8: =+$X$7/12 -> 458.33333 | Y8: =(K8*85%)*$Y$7 -> 0 | Z8: =+$Z$7 -> 0.6 | AA8: =+$AA$7/12 -> 458.33333 | AB8: =+$AB$7/12 -> 0 | AC8: =K8*$AC$7 -> 0 | AD8: =K8*$AD$7 -> 0 | AE8: =K8*$AE$7 -> 153992.25 | AF8: =+K8*$AF$7 -> 61596.9 | AG8: =K8*$AG$7+SUM(C8:D8)*(1/(12*2)) -> 365610.75 | AH8: =+$AH$7 -> 0 | AI8: =+SUM(K8:AH8) -> 4468882.8 | AJ8: =+AI8/$AJ$7 -> 22344.414 | AL8: =+((C8)-(C8)*17%) -> 2171638.6 | AM8: =+O8 -> 0 | AN8: =+D8-D8*17% -> 830 | AO8: =+AL8+AM8+AN8 -> 2172468.6 | AQ8: =+AI8/AO8 -> 2.0570529
B9: JEFE DE S&SO, MA y CALIDAD | C9: =1.4*450000*2*1.5 -> 1890000 | D9: 1000 | E9: =+C9+D9 -> 1891000 | G9: =+((C9+D9)*$G$7) -> 0 | H9: =(C9+D9+G9)/12 -> 157583.33 | I9: =((SUM(C9:G9)/25)*$I$7)/12 -> 176493.33 | J9: =((C9/191)*$J$7)/12 -> 0 | K9: =+E9+SUM(G9:J9) -> 2225076.7 | L9: =K9*$L$7 -> 489516.87 | N9: =K9*$N$7 -> 93453.22 | O9: =(C9)*$O$7 -> 0 | P9: =O9/12 -> 0 | Q9: =(O9+P9)*$Q$7 -> 0 | R9: =(O9+P9)*$R$7 -> 0 | S9: =+$S$7 -> 1.3 | U9: =+$U$7 -> 0 | V9: =+$V$7 -> 0 | W9: =+$W$7 -> 0 | X9: =+$X$7/12 -> 458.33333 | Y9: =(K9*85%)*$Y$7 -> 0 | Z9: =+$Z$7 -> 0.6 | AA9: =+$AA$7/12 -> 458.33333 | AB9: =+$AB$7/12 -> 0 | AC9: =K9*$AC$7 -> 0 | AD9: =K9*$AD$7 -> 0 | AE9: =K9*$AE$7 -> 111253.83 | AF9: =+K9*$AF$7 -> 44501.533 | AG9: =K9*$AG$7+SUM(C9:D9)*(1/(12*3)) -> 237876.66 | AH9: =+$AH$7 -> 0 | AI9: =+SUM(K9:AH9) -> 3202597.4 | AJ9: =+AI9/$AJ$7 -> 16012.987 | AL9: =+((C9)-(C9)*17%) -> 1568700 | AM9: =+O9 -> 0 | AN9: =+D9-D9*17% -> 830 | AO9: =+AL9+AM9+AN9 -> 1569530 | AQ9: =+AI9/AO9 -> 2.0404818
B10: TECNICOS SEGURIDAD | C10: =1.4*400000*2.5*1.3 -> 1820000 | D10: 1000 | E10: =+C10+D10 -> 1821000 | G10: =+((C10+D10)*$G$7) -> 0 | H10: =(C10+D10+G10)/12 -> 151750 | I10: =((SUM(C10:G10)/25)*$I$7)/12 -> 169960 | J10: =((C10/191)*$J$7)/12 -> 0 | K10: =+E10+SUM(G10:J10) -> 2142710 | L10: =K10*$L$7 -> 471396.2 | N10: =K10*$N$7 -> 89993.82 | O10: =(C10)*$O$7 -> 0 | P10: =O10/12 -> 0 | Q10: =(O10+P10)*$Q$7 -> 0 | R10: =(O10+P10)*$R$7 -> 0 | S10: =+$S$7 -> 1.3 | U10: =+$U$7 -> 0 | V10: =+$V$7 -> 0 | W10: =+$W$7 -> 0 | X10: =+$X$7/12 -> 458.33333 | Y10: =(K10*85%)*$Y$7 -> 0 | Z10: =+$Z$7 -> 0.6 | AA10: =+$AA$7/12 -> 458.33333 | AB10: =+$AB$7/12 -> 0 | AC10: =K10*$AC$7 -> 0 | AD10: =K10*$AD$7 -> 0 | AE10: =K10*$AE$7 -> 107135.5 | AF10: =+K10*$AF$7 -> 42854.2 | AG10: =K10*$AG$7+SUM(C10:D10)*(1/(12*3)) -> 229071.08 | AH10: =+$AH$7 -> 0 | AI10: =+SUM(K10:AH10) -> 3084079.4 | AJ10: =+AI10/$AJ$7 -> 15420.397 | AL10: =+((C10)-(C10)*17%) -> 1510600 | AM10: =+O10 -> 0 | AN10: =+D10-D10*17% -> 830 | AO10: =+AL10+AM10+AN10 -> 1511430 | AQ10: =+AI10/AO10 -> 2.0405043
A11: =15000000/0.83 -> 18072289 | B11: SUPERVISOR | C11: =1.4*300000*2*2.2 -> 1848000 | D11: 1000 | E11: =+C11+D11 -> 1849000 | G11: =+((C11+D11)*$G$7) -> 0 | H11: =(C11+D11+G11)/12 -> 154083.33 | I11: =((SUM(C11:G11)/25)*$I$7)/12 -> 172573.33 | J11: =((C11/191)*$J$7)/12 -> 0 | K11: =+E11+SUM(G11:J11) -> 2175656.7 | L11: =K11*$L$7 -> 478644.47 | N11: =K11*$N$7 -> 91377.58 | O11: =(C11)*$O$7 -> 0 | P11: =O11/12 -> 0 | Q11: =(O11+P11)*$Q$7 -> 0 | R11: =(O11+P11)*$R$7 -> 0 | S11: =+$S$7 -> 1.3 | U11: =+$U$7 -> 0 | V11: =+$V$7 -> 0 | W11: =+$W$7 -> 0 | X11: =+$X$7/12 -> 458.33333 | Y11: =(K11*85%)*$Y$7 -> 0 | Z11: =+$Z$7 -> 0.6 | AA11: =+$AA$7/12 -> 458.33333 | AB11: =+$AB$7/12 -> 0 | AC11: =K11*$AC$7 -> 0 | AD11: =K11*$AD$7 -> 0 | AE11: =K11*$AE$7 -> 108782.83 | AF11: =+K11*$AF$7 -> 43513.133 | AG11: =K11*$AG$7+SUM(C11:D11)*(1/(12*3)) -> 232593.31 | AH11: =+$AH$7 -> 0 | AI11: =+SUM(K11:AH11) -> 3131486.6 | AJ11: =+AI11/$AJ$7 -> 15657.433 | AL11: =+((C11)-(C11)*17%) -> 1533840 | AM11: =+O11 -> 0 | AN11: =+D11-D11*17% -> 830 | AO11: =+AL11+AM11+AN11 -> 1534670 | AQ11: =+AI11/AO11 -> 2.0404951
B12: ADMINISTRATIVO | C12: =1.4*250000*2*1.5 -> 1050000 | D12: 1000 | E12: =+C12+D12 -> 1051000 | G12: =+((C12+D12)*$G$7) -> 0 | H12: =(C12+D12+G12)/12 -> 87583.333 | I12: =((SUM(C12:G12)/25)*$I$7)/12 -> 98093.333 | J12: =((C12/191)*$J$7)/12 -> 0 | K12: =+E12+SUM(G12:J12) -> 1236676.7 | L12: =K12*$L$7 -> 272068.87 | N12: =K12*$N$7 -> 51940.42 | O12: =(C12)*$O$7 -> 0 | P12: =O12/12 -> 0 | Q12: =(O12+P12)*$Q$7 -> 0 | R12: =(O12+P12)*$R$7 -> 0 | S12: =+$S$7 -> 1.3 | U12: =+$U$7 -> 0 | V12: =+$V$7 -> 0 | W12: =+$W$7 -> 0 | X12: =+$X$7/12 -> 458.33333 | Y12: =(K12*85%)*$Y$7 -> 0 | Z12: =+$Z$7 -> 0.6 | AA12: =+$AA$7/12 -> 458.33333 | AB12: =+$AB$7/12 -> 0 | AC12: =K12*$AC$7 -> 0 | AD12: =K12*$AD$7 -> 0 | AE12: =K12*$AE$7 -> 61833.833 | AF12: =+K12*$AF$7 -> 24733.533 | AG12: =K12*$AG$7+SUM(C12:D12)*(1/(12*3)) -> 132209.61 | AH12: =+$AH$7 -> 0 | AI12: =+SUM(K12:AH12) -> 1780381.5 | AJ12: =+AI12/$AJ$7 -> 8901.9075 | AL12: =+((C12)-(C12)*17%) -> 871500 | AM12: =+O12 -> 0 | AN12: =+D12-D12*17% -> 830 | AO12: =+AL12+AM12+AN12 -> 872330 | AQ12: =+AI12/AO12 -> 2.0409495
B13: PAÑOLERO | C13: =1.4*250000*2*1.5 -> 1050000 | D13: 1000 | E13: =+C13+D13 -> 1051000 | G13: =+((C13+D13)*$G$7) -> 0 | H13: =(C13+D13+G13)/12 -> 87583.333 | I13: =((SUM(C13:G13)/25)*$I$7)/12 -> 98093.333 | J13: =((C13/191)*$J$7)/12 -> 0 | K13: =+E13+SUM(G13:J13) -> 1236676.7 | L13: =K13*$L$7 -> 272068.87 | N13: =K13*$N$7 -> 51940.42 | O13: =(C13)*$O$7 -> 0 | P13: =O13/12 -> 0 | Q13: =(O13+P13)*$Q$7 -> 0 | R13: =(O13+P13)*$R$7 -> 0 | S13: =+$S$7 -> 1.3 | U13: =+$U$7 -> 0 | V13: =+$V$7 -> 0 | W13: =+$W$7 -> 0 | X13: =+$X$7/12 -> 458.33333 | Y13: =(K13*85%)*$Y$7 -> 0 | Z13: =+$Z$7 -> 0.6 | AA13: =+$AA$7/12 -> 458.33333 | AB13: =+$AB$7/12 -> 0 | AC13: =K13*$AC$7 -> 0 | AD13: =K13*$AD$7 -> 0 | AE13: =K13*$AE$7 -> 61833.833 | AF13: =+K13*$AF$7 -> 24733.533 | AG13: =K13*$AG$7+SUM(C13:D13)*(1/(12*3)) -> 132209.61 | AH13: =+$AH$7 -> 0 | AI13: =+SUM(K13:AH13) -> 1780381.5 | AJ13: =+AI13/$AJ$7 -> 8901.9075 | AL13: =+((C13)-(C13)*17%) -> 871500 | AM13: =+O13 -> 0 | AN13: =+D13-D13*17% -> 830 | AO13: =+AL13+AM13+AN13 -> 872330 | AQ13: =+AI13/AO13 -> 2.0409495
B14: CHOFER | C14: =1.4*250000*2*1.5 -> 1050000 | D14: 1000 | E14: =+C14+D14 -> 1051000 | G14: =+((C14+D14)*$G$7) -> 0 | H14: =(C14+D14+G14)/12 -> 87583.333 | I14: =((SUM(C14:G14)/25)*$I$7)/12 -> 98093.333 | J14: =((C14/191)*$J$7)/12 -> 0 | K14: =+E14+SUM(G14:J14) -> 1236676.7 | L14: =K14*$L$7 -> 272068.87 | N14: =K14*$N$7 -> 51940.42 | O14: =(C14)*$O$7 -> 0 | P14: =O14/12 -> 0 | Q14: =(O14+P14)*$Q$7 -> 0 | R14: =(O14+P14)*$R$7 -> 0 | S14: =+$S$7 -> 1.3 | U14: =+$U$7 -> 0 | V14: =+$V$7 -> 0 | W14: =+$W$7 -> 0 | X14: =+$X$7/12 -> 458.33333 | Y14: =(K14*85%)*$Y$7 -> 0 | Z14: =+$Z$7 -> 0.6 | AA14: =+$AA$7/12 -> 458.33333 | AB14: =+$AB$7/12 -> 0 | AC14: =K14*$AC$7 -> 0 | AD14: =K14*$AD$7 -> 0 | AE14: =K14*$AE$7 -> 61833.833 | AF14: =+K14*$AF$7 -> 24733.533 | AG14: =K14*$AG$7+SUM(C14:D14)*(1/(12*3)) -> 132209.61 | AH14: =+$AH$7 -> 0 | AI14: =+SUM(K14:AH14) -> 1780381.5 | AJ14: =+AI14/$AJ$7 -> 8901.9075 | AL14: =+((C14)-(C14)*17%) -> 871500 | AM14: =+O14 -> 0 | AN14: =+D14-D14*17% -> 830 | AO14: =+AL14+AM14+AN14 -> 872330 | AQ14: =+AI14/AO14 -> 2.0409495
B15: LIMPIEZA | C15: =1.4*250000*2*1.5 -> 1050000 | D15: 1000 | E15: =+C15+D15 -> 1051000 | G15: =+((C15+D15)*$G$7) -> 0 | H15: =(C15+D15+G15)/12 -> 87583.333 | I15: =((SUM(C15:G15)/25)*$I$7)/12 -> 98093.333 | J15: =((C15/191)*$J$7)/12 -> 0 | K15: =+E15+SUM(G15:J15) -> 1236676.7 | L15: =K15*$L$7 -> 272068.87 | N15: =K15*$N$7 -> 51940.42 | O15: =(C15)*$O$7 -> 0 | P15: =O15/12 -> 0 | Q15: =(O15+P15)*$Q$7 -> 0 | R15: =(O15+P15)*$R$7 -> 0 | S15: =+$S$7 -> 1.3 | U15: =+$U$7 -> 0 | V15: =+$V$7 -> 0 | W15: =+$W$7 -> 0 | X15: =+$X$7/12 -> 458.33333 | Y15: =(K15*85%)*$Y$7 -> 0 | Z15: =+$Z$7 -> 0.6 | AA15: =+$AA$7/12 -> 458.33333 | AB15: =+$AB$7/12 -> 0 | AC15: =K15*$AC$7 -> 0 | AD15: =K15*$AD$7 -> 0 | AE15: =K15*$AE$7 -> 61833.833 | AF15: =+K15*$AF$7 -> 24733.533 | AG15: =K15*$AG$7+SUM(C15:D15)*(1/(12*3)) -> 132209.61 | AH15: =+$AH$7 -> 0 | AI15: =+SUM(K15:AH15) -> 1780381.5 | AJ15: =+AI15/$AJ$7 -> 8901.9075 | AL15: =+((C15)-(C15)*17%) -> 871500 | AM15: =+O15 -> 0 | AN15: =+D15-D15*17% -> 830 | AO15: =+AL15+AM15+AN15 -> 872330 | AQ15: =+AI15/AO15 -> 2.0409495

Sheet 2 SUMINISTRO DE MATERIALES
C1: 2 - SUMINISTRO DE MATERIALES
B3: CLIENTE: | C3: ='Sintesis Economica'!C2 -> PAMPA | F3: J. de PROYECTO: | G3: ='Sintesis Economica'!J2 -> SHM
B4: OBRA : | C4: ='Sintesis Economica'!C3 -> PAMPA SERVICIOS MENORES CIVILES | F4: Elaboró: | G4: ='Sintesis Economica'!J3 -> SHM
B5: PLIEGO / E.T.P.Nº: | C5: ='Sintesis Economica'!C5 -> Nº LICITACIÓN: SIN | F5: Revisó: | G5: ='Sintesis Economica'!J4 -> 0
B6: OFERTA N°: | C6: ='Sintesis Economica'!C6 -> PRE-ARG-1340
C7: TOTAL COSTO SUMINISTRO DE MATERIALES | G7: =+G20+G33+G39+G51 -> 0
B8: 2.1 MATERIALES MECANICOS
B9: ITEM | C9: DESCRIPCION | D9: PRECIO UNITARIO | E9: U | F9: CANT. | G9: COSTO TOTAL
B10: 2.1.1 | G10: =+F10*D10 -> 0
B11: 2.1.2 | G11: =+F11*D11 -> 0
B12: 2.1.3 | G12: =+F12*D12 -> 0
B13: 2.1.4 | G13: =+F13*D13 -> 0
B14: 2.1.5 | G14: =+F14*D14 -> 0
B15: 2.1.6 | G15: =+F15*D15 -> 0
B16: 2.1.7 | G16: =+F16*D16 -> 0
B17: 2.1.8 | G17: =+F17*D17 -> 0
B18: 2.1.9 | G18: =+F18*D18 -> 0
B19: 2.1.10 | G19: =+F19*D19 -> 0
B20: SUBTOTAL MATERIALES MECÁNICOS | G20: =SUM(G10:G19) -> 0
C21: 2.2 MATERIALES ELÉCTRICOS
B22: ITEM | C22: DESCRIPCION | D22: PRECIO UNITARIO | E22: U | F22: CANT. | G22: COSTO TOTAL
B23: 2.2.1 | G23: =+F23*D23 -> 0
B24: 2.2.2 | G24: =+F24*D24 -> 0
B25: 2.2.3 | G25: =+F25*D25 -> 0
B26: 2.2.4 | G26: =+F26*D26 -> 0
B27: 2.2.5 | G27: =+F27*D27 -> 0
B28: 2.2.6 | G28: =+F28*D28 -> 0
B29: 2.2.7 | G29: =+F29*D29 -> 0
B30: 2.2.8 | G30: =+F30*D30 -> 0
B31: 2.2.9 | G31: =+F31*D31 -> 0
B32: 2.2.10 | G32: =+F32*D32 -> 0
B33: SUBTOTAL MATERIALES ELECTRICOS | G33: =SUM(G23:G32) -> 0
B34: 2.3 MATERIALES AUTOMACION E INFORMATICOS
B35: ITEM | C35: DESCRIPCION | D35: PRECIO UNITARIO | E35: U | F35: CANTIDAD | G35: COSTO TOTAL
B36: 2.3.1 | G36: =+F36*D36 -> 0
B37: 2.3.2 | G37: =+F37*D37 -> 0
B38: 2.3.3 | G38: =+F38*D38 -> 0
B39: SUBTOTAL MATERIALES AUTOMACION E INFORMATICOS | G39: =SUM(G36:G38) -> 0
B40: 2.4 MATERIALES DIVERSOS
B41: ITEM | C41: DESCRIPCION | D41: PRECIO UNITARIO | E41: U | F41: CANTIDAD | G41: COSTO TOTAL
...

Sheet 3 SUMINISTRO DE INSUMOS
C1: 3- SUMINISTRO DE INSUMOS CONSUMIBLES
B3: CLIENTE: | C3: ='Sintesis Economica'!C2 -> PAMPA | E3: J. de PROYECTO: | F3: ='Sintesis Economica'!J2 -> SHM
B4: OBRA : | C4: ='Sintesis Economica'!C3 -> PAMPA SERVICIOS MENORES CIVILES | E4: Elaboró: | F4: ='Sintesis Economica'!J3 -> SHM
B5: PLIEGO / E.T.P.Nº: | C5: ='Sintesis Economica'!C5 -> Nº LICITACIÓN: SIN | E5: Revisó: | F5: ='Sintesis Economica'!J4 -> 0
B6: OFERTA N°: | C6: ='Sintesis Economica'!C6 -> PRE-ARG-1340
B7: TOTAL COSTO de INSUMOS CONSUMIBLES | F7: =+F39+F54+F61+F68+F87+F96 -> 2787372.8 | G7: =+F7/#REF! -> #REF!
B8: 3.1 INSUMOS CONSUMIBLES (INSUMOS DIRECTOS DE MANTENIMIENTO Y OPERACIÓN)
B9: ITEM | C9: DESCRIPCION | D9: PRECIO UNITARIO | E9: CANT. | F9: COSTO TOTAL
B10: 3.1.1 | C10: insumos | D10: 400 | E10: ='1 MANO DE OBRA'!C24 -> 1309 | F10: =+E10*D10 -> 523600 | H10: 2 | I10: COSTO POR HH DE INSUMOS GRALES
B11: 3.1.2 | F11: =+E11*D11 -> 0
B12: 3.1.3 | F12: =+E12*D12 -> 0
B13: 3.1.4 | F13: =+E13*D13 -> 0
B14: 3.1.5 | F14: =+E14*D14 -> 0
B15: 3.1.6 | F15: =+E15*D15 -> 0
B16: 3.1.7 | F16: =+E16*D16 -> 0
B17: 3.1.8 | F17: =+E17*D17 -> 0
B18: 3.1.9 | F18: =+E18*D18 -> 0
B19: 3.1.10 | F19: =+E19*D19 -> 0
B20: 3.1.11 | F20: =+E20*D20 -> 0
B21: 3.1.12 | F21: =+E21*D21 -> 0
B22: 3.1.13 | F22: =+E22*D22 -> 0
... B38: 3.1.29 | F38: =+E38*D38 -> 0
B39: SUBTOTAL INSUMOS CONSUMIBLES (INSUMOS DIRECTOS DE MANTENIMIENTO) | F39: =SUM(F10:F38) -> 523600 | G39: =+F39/#REF! -> #REF!
C41: 3.2 COMBUSTIBLE, FILTROS Y LUBRICATES DE RODADOS Y MÁQUINAS
B42: ITEM | C42: DESCRIPCION | D42: PRECIO UNITARIO | E42: CANT. | F42: COSTO TOTAL | I42: CONSUMO DE COMBUSTIBLE | J42: HS/DIA | K42: LTS/HS | L42: DIAS | M42: CTD | N42: TOTAL LTS
B43: 3.2.1 | C43: Combustible | D43: 2500 | E43: =70*4*2 -> 560 | F43: =+E43*D43 -> 1400000 | I43: =+'5 AMORTIZACIÓN'!C11 -> alaskan | J43: 10 | K43: 1.5 | L43: 22 | M43: 2 | N43: =+J43*K43*L43 -> 330 | O43: =M43*N43 -> 660
B44: 3.2.2 | F44: =+E44*D44 -> 0 | I44: =+'5 AMORTIZACIÓN'!C12 -> partner | J44: 10 | K44: 3 | L44: 22 | M44: 2 | N44: =+J44*K44*L44 -> 660 | O44: =M44*N44 -> 1320
B45: 3.2.3 | F45: =+E45*D45 -> 0 | I45: =+'5 AMORTIZACIÓN'!C13 -> 0 | J45: 10 | K45: 3 | L45: 22 | M45: ='5 AMORTIZACIÓN'!E13 -> 0 | N45: =+J45*K45*L45 -> 660 | O45: =M45*N45 -> 0
B46: 3.2.4 | F46: =+E46*D46 -> 0 | I46: =+'5 AMORTIZACIÓN'!C14 -> 0 | J46: 10 | K46: 3 | L46: 22 | M46: ='5 AMORTIZACIÓN'!E14 -> 0 | N46: =+J46*K46*L46 -> 660 | O46: =M46*N46 -> 0
B47: 3.2.5 | F47: =+E47*D47 -> 0 | I47: =+'5 AMORTIZACIÓN'!C15 -> 0 | J47: 10 | K47: 3 | L47: 22 | M47: ='5 AMORTIZACIÓN'!E15 -> 0 | N47: =+J47*K47*L47 -> 660 | O47: =M47*N47 -> 0
B48: 3.2.6 | F48: =+E48*D48 -> 0 | I48: =+'5 AMORTIZACIÓN'!C16 -> 0
B49: 3.2.7 | F49: =+E49*D49 -> 0
B50: 3.2.8 | F50: =+E50*D50 -> 0 | M50: =+SUM(M43:M49) -> 4 | N50: =+SUM(N43:N49) -> 2970 | O50: =+SUM(O43:O49) -> 1980
B51: 3.2.9 | F51: =+E51*D51 -> 0
B52: 3.2.10 | F52: =+E52*D52 -> 0
B53: 3.2.11 | F53: =+E53*D53 -> 0
B54: SUBTOTAL COMBUSTIBLE, FILTROS Y LUBRICATES | F54: =SUM(F43:F53) -> 1400000 | G54: =+F54/#REF! -> #REF!
B56: 3.3 INSUMOS INFORMÁTICOS Y DE OFICINA
B57: ITEM | C57: DESCRIPCION | D57: PRECIO UNITARIO | E57: CANTIDAD | F57: COSTO TOTAL
B58: 3.3.1 | C58: PAPELERIA | D58: 15000 | E58: 1 | F58: =+E58*D58 -> 15000
...

Sheet 4 SUBCONTRATACIONES
B1: 4 - SUBCONTRATACIONES
B3: CLIENTE: | C3: ='Sintesis Economica'!C2 -> PAMPA | E3: J. de PROYECTO: | F3: ='Sintesis Economica'!J2 -> SHM
B4: OBRA : | C4: ='Sintesis Economica'!C3 -> PAMPA SERVICIOS MENORES CIVILES | E4: Elaboró: | F4: ='Sintesis Economica'!J3 -> SHM
B5: PLIEGO / E.T.P.Nº: | C5: ='Sintesis Economica'!C5 -> Nº LICITACIÓN: SIN | E5: Revisó: | F5: ='Sintesis Economica'!J4 -> 0
B6: OFERTA N°: | C6: ='Sintesis Economica'!C6 -> PRE-ARG-1340
B7: TOTAL COSTO DE SUBCONTRATACIONES | F7: =+F26+F47+F68+F89+F110 -> 100000
B8: 4.1 HONORARIOS PROFESIONALES
B9: ITEM | C9: DESCRIPCION | D9: PRECIO UNITARIO | E9: CANT. | F9: COSTO TOTAL
B10: 4.1.1 | C10: MICROSOFT 365 | D10: 50000 | E10: 1 | F10: =+E10*D10 -> 50000
B11: 4.1.2 | C11: Field | D11: 50000 | E11: 1 | F11: =+E11*D11 -> 50000
B12: 4.1.3 | F12: =+E12*D12 -> 0
B13: 4.1.4 | F13: =+E13*D13 -> 0
B14: 4.1.5 | F14: =+E14*D14 -> 0
B15: 4.1.6 | F15: =+E15*D15 -> 0
B16: 4.1.7 | F16: =+E16*D16 -> 0
B17: 4.1.8 | F17: =+E17*D17 -> 0
B18: 4.1.9 | F18: =+E18*D18 -> 0
B19: 4.1.10 | F19: =+E19*D19 -> 0
B20: 4.1.11 | F20: =+E20*D20 -> 0
B21: 4.1.12 | F21: =+E21*D21 -> 0
B22: 4.1.13 | F22: =+E22*D22 -> 0
B23: 4.1.14 | F23: =+E23*D23 -> 0
... B25: 4.1.16 | F25: =+E25*D25 -> 0
B26: SUBTOTAL HONORARIOS PROFESIONALES | F26: =SUM(F10:F25) -> 100000
B29: 4.2 SERVICIOS TECNICOS ESPECIALIZADOS
B30: ITEM | C30: DESCRIPCION | D30: PRECIO UNITARIO | E30: CANT. | F30: COSTO TOTAL
B31: 4.2.1 | F31: =+E31*D31 -> 0 | G31: 0
B32: 4.2.2 | F32: =+E32*D32 -> 0
B33: 4.2.3 | F33: =+E33*D33 -> 0
B34: 4.2.4 | F34: =+E34*D34 -> 0
B35: 4.2.5 | F35: =+E35*D35 -> 0
B36: 4.2.6 | F36: =+E36*D36 -> 0
B37: 4.2.7 | F37: =+E37*D37 -> 0
B38: 4.2.8 | F38: =+E38*D38 -> 0
B39: 4.2.9 | F39: =+E39*D39 -> 0
B40: 4.2.10 | F40: =+E40*D40 -> 0
B41: 4.2.11 | F41: =+E41*D41 -> 0
B42: 4.2.12 | F42: =+E42*D42 -> 0
B43: 4.2.13 | F43: =+E43*D43 -> 0
... B46: 4.2.16 | F46: =+E46*D46 -> 0
...

Sheet 5 AMORTIZACIÓN
B1: 5- MONTO DE INVERSIÓN Y CÁLCULO DE AMORTIZACIÓN MENSUAL
B3: CLIENTE: | C3: ='Sintesis Economica'!C2 -> PAMPA
B4: OBRA : | C4: ='Sintesis Economica'!C3 -> PAMPA SERVICIOS MENORES CIVILES | I4: Jefe de Proyecto: | J4: ='Sintesis Economica'!J2 -> SHM
B5: PLIEGO / E.T.P.Nº: | C5: ='Sintesis Economica'!C5 -> Nº LICITACIÓN: SIN | I5: Elaboró: | J5: ='Sintesis Economica'!J3 -> SHM
B6: OFERTA N°: | C6: ='Sintesis Economica'!C6 -> PRE-ARG-1340 | I6: Revisó: | J6: ='Sintesis Economica'!J4 -> 0
B8: TOTAL MENSUAL AMORTIZABLE | J8: =(K10+K23+K36+K49+K62+K75) -> 3906741.8
B9: ITEM | C9: Descripción | D9: Costo Unit. | E9: Cant. | F9: Inversión | G9: Plazo de amortización (en años) | H9: Valor Residual | J9: Costo Financiero | K9: AMORTIZACIÓN MENSUAL
B10: 5.1 | C10: RODADOS Y EQUIPOS MOVILES ESPECIALES | F10: =SUM(F11:F22) -> 115000000 | I10: =SUM(I11:I22) -> 57500000 | J10: 0.02 | K10: =SUM(K11:K22)*-1 -> 2804158
B11: 5.1.1 | C11: alaskan | D11: 70000000 | E11: 1 | F11: =+D11*E11 -> 70000000 | G11: 5 | H11: 0.5 | I11: =+F11*H11 -> 35000000 | J11: =+$J$10 -> 0.02 | K11: =PMT(J11,G11*12,F11-I11,0)-I11*J11 -> -1706878.8
B12: 5.1.2 | C12: partner | D12: 45000000 | E12: 1 | F12: =+D12*E12 -> 45000000 | G12: 5 | H12: 0.5 | I12: =+F12*H12 -> 22500000 | J12: =+$J$10 -> 0.02 | K12: =PMT(J12,G12*12,F12-I12,0)-I12*J12 -> -1097279.2
B13: 5.1.3 | F13: =+D13*E13 -> 0 | G13: 5 | H13: 0.5 | I13: =+F13*H13 -> 0 | J13: =+$J$10 -> 0.02 | K13: =PMT(J13,G13*12,F13-I13,0)-I13*J13 -> 0
B14: 5.1.4 | F14: =+D14*E14 -> 0 | G14: 5 | H14: 0.4 | I14: =+F14*H14 -> 0 | J14: =+$J$10 -> 0.02 | K14: =PMT(J14,G14*12,F14-I14,0)-I14*J14 -> 0
B15: 5.1.5 | F15: =+D15*E15 -> 0 | G15: 5 | H15: 0.4 | I15: =+F15*H15 -> 0 | J15: =+$J$10 -> 0.02 | K15: =PMT(J15,G15*12,F15-I15,0)-I15*J15 -> 0
B16: 5.1.6 | F16: =+D16*E16 -> 0 | G16: 5 | H16: 0.4 | I16: =+F16*H16 -> 0 | J16: =+$J$10 -> 0.02 | K16: =PMT(J16,G16*12,F16-I16,0)-I16*J16 -> 0
B17: 5.1.7 | F17: =+D17*E17 -> 0 | G17: 3 | H17: 0.4 | I17: =+F17*H17 -> 0 | J17: =+$J$10 -> 0.02 | K17: =PMT(J17,G17*12,F17-I17,0)-I17*J17 -> 0
B18: 5.1.8 | F18: =+D18*E18 -> 0 | G18: 3 | H18: 0 | I18: =+F18*H18 -> 0 | J18: =+$J$10 -> 0.02 | K18: =PMT(J18,G18*12,F18-I18,0)-I18*J18 -> 0
B19: 5.1.9 | F19: =+D19*E19 -> 0 | G19: 3 | H19: 0 | I19: =+F19*H19 -> 0 | J19: =+$J$10 -> 0.02 | K19: =PMT(J19,G19*12,F19-I19,0)-I19*J19 -> 0
B20: 5.1.10 | F20: =+D20*E20 -> 0 | G20: 3 | H20: 0.3 | I20: =+F20*H20 -> 0 | J20: =+$J$10 -> 0.02 | K20: =PMT(J20,G20*12,F20-I20,0)-I20*J20 -> 0
B21: 5.1.11 | F21: =+D21*E21 -> 0 | G21: 3 | H21: 0 | I21: =+F21*H21 -> 0 | J21: =+$J$10 -> 0.02 | K21: =PMT(J21,G21*12,F21-I21,0)-I21*J21 -> 0
B22: 5.1.12 | F22: =+D22*E22 -> 0 | G22: 3 | H22: 0 | I22: =+F22*H22 -> 0 | J22: =+$J$10 -> 0.02 | K22: =PMT(J22,G22*12,F22-I22,0)-I22*J22 -> 0
B23: 5.2 | C23: MUEBLES Y ÚTILES | F23: =SUM(F24:F35) -> 1500000 | I23: =SUM(I24:I35) -> 0 | K23: =SUM(K24:K35)*-1 -> 141839.39
B24: 5.2.1 | C24: contenedor (SOLO TRALSADO) | D24: 1500000 | E24: 1 | F24: =+D24*E24 -> 1500000 | G24: 1 | H24: 0 | I24: =+F24*H24 -> 0 | J24: =+$J$10 -> 0.02 | K24: =PMT(J24,G24*12,F24-I24,0)-I24*J24 -> -141839.39
B25: 5.2.2 | F25: =+D25*E25 -> 0 | G25: 8 | H25: 0.8 | I25: =+F25*H25 -> 0 | J25: =+$J$10 -> 0.02 | K25: =PMT(J25,G25*12,F25-I25,0)-I25*J25 -> 0
B26: 5.2.3 | F26: =+D26*E26 -> 0 | G26: 3 | H26: 0 | I26: =+F26*H26 -> 0 | J26: =+$J$10 -> 0.02 | K26: =PMT(J26,G26*12,F26-I26,0)-I26*J26 -> 0
B27: 5.2.4 | F27: =+D27*E27 -> 0 | G27: 3 | H27: 0 | I27: =+F27*H27 -> 0 | J27: =+$J$10 -> 0.02 | K27: =PMT(J27,G27*12,F27-I27,0)-I27*J27 -> 0
B28: 5.2.5 | F28: =+D28*E28 -> 0 | G28: 3 | H28: 0 | I28: =+F28*H28 -> 0 | J28: =+$J$10 -> 0.02 | K28: =PMT(J28,G28*12,F28-I28,0)-I28*J28 -> 0
B29: 5.2.6 | F29: =+D29*E29 -> 0 | G29: 3 | H29: 0 | I29: =+F29*H29 -> 0 | J29: =+$J$10 -> 0.02 | K29: =PMT(J29,G29*12,F29-I29,0)-I29*J29 -> 0
B30: 5.2.7 | F30: =+D30*E30 -> 0 | G30: 3 | H30: 0 | I30: =+F30*H30 -> 0 | J30: =+$J$10 -> 0.02 | K30: =PMT(J30,G30*12,F30-I30,0)-I30*J30 -> 0
B31: 5.2.8 | F31: =+D31*E31 -> 0 | G31: 3 | H31: 0 | I31: =+F31*H31 -> 0 | J31: =+$J$10 -> 0.02 | K31: =PMT(J31,G31*12,F31-I31,0)-I31*J31 -> 0
B32: 5.2.9 | F32: =+D32*E32 -> 0 | G32: 3 | H32: 0 | I32: =+F32*H32 -> 0 | J32: =+$J$10 -> 0.02 | K32: =PMT(J32,G32*12,F32-I32,0)-I32*J32 -> 0
B33: 5.2.10 | F33: =+D33*E33 -> 0 | G33: 3 | H33: 0 | I33: =+F33*H33 -> 0 | J33: =+$J$10 -> 0.02 | K33: =PMT(J33,G33*12,F33-I33,0)-I33*J33 -> 0
B34: 5.2.11 | F34: =+D34*E34 -> 0 | G34: 3 | H34: 0 | I34: =+F34*H34 -> 0 | J34: =+$J$10 -> 0.02 | K34: =PMT(J34,G34*12,F34-I34,0)-I34*J34 -> 0
B35: 5.2.12 | F35: =+D35*E35 -> 0 | G35: 3 | H35: 0 | I35: =+F35*H35 -> 0 | J35: =+$J$10 -> 0.02 | K35: =PMT(J35,G35*12,F35-I35,0)-I35*J35 -> 0
B36: 5.3 | C36: INSTALACIÓNES Y ADECUACIÓN DE LOCALES | F36: =SUM(F37:F48) -> 0 | I36: =SUM(I37:I48) -> 0 | K36: =SUM(K37:K48)*-1 -> 0
B37: 5.3.1 | C37: VESTUARIO Y DUCHA | F37: =+D37*E37 -> 0 | G37: 8 | H37: 0.5 | I37: =+F37*H37 -> 0 | J37: =+$J$10 -> 0.02 | K37: =PMT(J37,G37*12,F37-I37,0)-I37*J37 -> 0
B38: 5.3.2 | C38: INSTALACION DEL CONTENEDOR ANTERIOR | F38: =+D38*E38 -> 0 | G38: 8 | H38: 0.5 | I38: =+F38*H38 -> 0 | J38: =+$J$10 -> 0.02 | K38: =PMT(J38,G38*12,F38-I38,0)-I38*J38 -> 0
B39: 5.3.3 | F39: =+D39*E39 -> 0 | G39: 5 | H39: 0 | I39: =+F39*H39 -> 0 | J39: =+$J$10 -> 0.02 | K39: =PMT(J39,G39*12,F39-I39,0)-I39*J39 -> 0
B40: 5.3.4 | F40: =+D40*E40 -> 0 | G40: 5 | H40: 0 | I40: =+F40*H40 -> 0 | J40: =+$J$10 -> 0.02 | K40: =PMT(J40,G40*12,F40-I40,0)-I40*J40 -> 0
B41: 5.3.5 | F41: =+D41*E41 -> 0 | G41: 3 | H41: 0 | I41: =+F41*H41 -> 0 | J41: =+$J$10 -> 0.02 | K41: =PMT(J41,G41*12,F41-I41,0)-I41*J41 -> 0
B42: 5.3.6 | F42: =+D42*E42 -> 0 | G42: 3 | H42: 0 | I42: =+F42*H42 -> 0 | J42: =+$J$10 -> 0.02 | K42: =PMT(J42,G42*12,F42-I42,0)-I42*J42 -> 0
...

Sheet Equipos
A3: ITEM | B3: DESCRIPCION | C3: CANTIDA | D3: PU | E3: $
G4: Å Equipo de soldadura portátil para trabajos menores.
G5: Å Agujereadoras de mano hasta 16 mm con sus mechas.
A6: 3 | B6: Equipo de soldadura portátil para trabajos menores. | C6: 6 | D6: 25000 | E6: =C6*D6 -> 150000 | G6: Å Agujereadora de banco con sus mandriles h/19mm.
A7: 4 | G7: Å Amoladoras de mano, eléctricas de 4” y 7”.
A8: 5 | G8: Å Llaves combinadas de 6 hasta 24mm.
A9: 6 | G9: Å Prolongaciones
A10: 7 | B10: Agujereadoras de mano hasta 16 mm con sus mechas. | C10: 6 | D10: 10000 | E10: =C10*D10 -> 60000 | G10: Å Atornilladora eléctrica.
A11: 8 | G11: Å Dobladoras de caños.
A12: 9 | B12: Agujereadora de banco con sus mandriles h/19mm. | C12: 4 | D12: 16000 | E12: =C12*D12 -> 64000 | G12: Å Dobladora hidraulica hasta 2”
A13: 10 | B13: Amoladoras de mano eléctricas o neumáticas de 4# y 7#. | C13: 6 | D13: 7000 | E13: =C13*D13 -> 42000 | G13: Å Roscadoras para caños hasta 2” eléctrica.
A14: 11 | G14: Å Morsa para caños hasta 4”.
A15: 12 | G15: Å Morsa de banco NRO 6
A16: 13 | G16: Å Bancos de trabajo
A17: 14 | G17: Å Meghómetros marca FLUKE.
A18: 15 | G18: Å Tester digital marca FLUKE .
A19: 16 | G19: Å Aspiradora para tableros eléctricos.
A20: 17 | G20: Å Pinza para identar terminales eléctricos.
A21: 18 | G21: Å Pinza amperométrica marca FLUKE .
A22: 19 | G22: Å Dispositivos para el tendido de cables.
A23: 20 | G23: Å Sogas. Varias
A24: 21 | G24: Å Extinguidores. Cap.10 kg
A25: 22 | G25: Å Lonas impermeables.
... A28: 25 | G28: Å Machos NPT y BSPT,un juego de c/uno hasta 2”
A29: 26 | B29: Llaves combinadas de 6 hasta 38mm. Cantidad mínima 12 juegos. | C29: 8 | D29: 20000 | E29: =C29*D29 -> 160000 | G29: Å Caladora eléctrica para chapa.
A30: 27 | G30: Å Tableros con disyuntores diferenciales, tipo T1-T2 completos.
A31: 28 | B31: Prolongaciones. | C31: 4 | D31: 3000 | E31: =C31*D31 -> 12000 | G31: Å Pinza corta cables.
A32: 29 | B32: Atornilladora eléctrica. | C32: 4 | D32: 10000 | E32: =C32*D32 -> 40000 | G32: Å Rotopercutor tipo HILTI T 76.
A33: 30 | G33: Å Otros-escuadras-adaptadores-balizas-cinta-mechas varias-niveles-pistolas-puntas-remachadoras-roldanas-mazas-llaves allen-tijeras-pinzas-alicates-francesas.
A34: 31
A35: 32 | G35: 1.1. Herramientas Generales Específicas de Redes:
A36: 33
A37: 34 | G37: Se dispondrán de los siguientes equipos para la prestación del servicio:
A38: 35
A39: 36 | B39: Dobladoras de caños (Farval). | C39: 2 | D39: 18665.99 | E39: =C39*D39 -> 37331.98 | G39: o Fusionadora de Fibra Óptica Jilong KL-300T, o similar (cantidad DOS).
A40: 37 | B40: Dobladoras hidráulicas ENERPAC hasta 2#. | C40: 2 | D40: 18665.99 | E40: =C40*D40 -> 37331.98 | G40: o Kit de herramientas (Peladora CFS-2, Tijera KS1, Abridora MK-02, Cort. de tubo buffer), cantidad DOS.
A41: 38 | B41: Roscadoras para caños hasta 4. | C41: 3 | D41: 30000 | E41: =C41*D41 -> 90000 | G41: o Visual Fault Locator-VLS6A (cantidad DOS).
A42: 39 | B42: Morsa para caños hasta 4. | C42: 3 | D42: 2000 | E42: =C42*D42 -> 6000 | G42: o Palm OTDR Shinewaytech, modelo M20A/E, o similar (cantidad DOS).
A43: 40 | B43: Morsa de banco NRO 6. | C43: 3 | D43: 2000 | E43: =C43*D43 -> 6000 | G43: o Certificador de Redes marca Certifier 40G, modelo NGC-4500 (cantidad UNO).
A44: 41 | B44: Bancos de trabajo con mesa de ajuste Nro.3 (mínimo 2 bancos). | C44: 3 | D44: 10000 | E44: =C44*D44 -> 30000 | G44: o Tester de red Fluke Micromapper MT8200-49A o similar (cantidad 6).
...
