Workbook

Sheet Datos del contrato
B4: Anexo B.2 - Alta Contrato | U4: versión 8_2025
C6: Aviso de Compra / contrato N°: | M6: (Ariba / Compra directa) | Q6: Fecha: | X6: =IF(AE6<>0,"Faltan datos","") -> Faltan datos | AB6: =IF(I6="",1,0) -> 1 | AC6: =IF(S6="",1,0) -> 1 | AE6: =SUM(AB6:AD6) -> 2
C10: Servicio / Obra : | X10: =IF(AE10<>0,"Faltan datos","") -> Faltan datos | AB10: =IF(G10="",1,0) -> 1 | AE10: =SUM(AB10:AD10) -> 1
C12: Planta / Yacimiento: | X12: =IF(AE12<>0,"Faltan datos","") -> Faltan datos | AB12: =IF(G12="",1,0) -> 1 | AE12: =SUM(AB12:AD12) -> 1
C14: Fecha Inicio: | O14: Fecha Finalización: | X14: =IF(AE14<>0,"Faltan datos","") -> Faltan datos | AB14: =IF(G14="",1,0) -> 1 | AC14: =IF(S14="",1,0) -> 1 | AE14: =SUM(AB14:AD14) -> 2
C16: Comprador: | X16: =IF(AE16<>0,"Faltan datos","") -> Faltan datos | AB16: =IF(G16="",1,0) -> 1 | AC16: =IF(O16="",1,0) -> 1 | AE16: =SUM(AB16:AD16) -> 2
C18: Gestor de contrato: | M18: Responsable contrato: | X18: =IF(AE18<>0,"Faltan datos","") -> Faltan datos | AB18: =IF(G18="",1,0) -> 1 | AC18: =IF(Q18="",1,0) -> 1 | AE18: =SUM(AB18:AD18) -> 2
C20: Mail Gestor: | M20: Mail Responsable: | X20: =IF(AE20<>0,"Faltan datos","") -> Faltan datos | AB20: =IF(G20="",1,0) -> 1 | AC20: =IF(Q20="",1,0) -> 1 | AE20: =SUM(AB20:AD20) -> 2
C24: Contratista (Razón Social): | Q24: Número de proveedor: | X24: =IF(AE24<>0,"Faltan datos","") -> Faltan datos | AB24: =IF(G24="",1,0) -> 1 | AC24: =IF(U24="",1,0) -> 1 | AE24: =SUM(AB24:AD24) -> 2
C26: CUIT N°: | K26: Domicilio: | X26: =IF(AE26<>0,"Faltan datos","") -> Faltan datos | AB26: =IF(E26="",1,0) -> 1 | AC26: =IF(M26="",1,0) -> 1 | AE26: =SUM(AB26:AD26) -> 2
C28: Ciudad: | K28: CP: | O28: Provincia: | X28: =IF(AE28<>0,"Faltan datos","") -> Faltan datos | AB28: =IF(E28="",1,0) -> 1 | AC28: =IF(M28="",1,0) -> 1 | AD28: =IF(Q28="",1,0) -> 1 | AE28: =SUM(AB28:AD28) -> 3
C30: Contacto: | Q30: Teléfonos: | X30: =IF(AE30<>0,"Faltan datos","") -> Faltan datos | AB30: =IF(E30="",1,0) -> 1 | AC30: =IF(S30="",1,0) -> 1 | AE30: =SUM(AB30:AD30) -> 2
C32: E mail: | Q32: Celular: | X32: =IF(AE32<>0,"Faltan datos","") -> Faltan datos | AB32: =IF(E32="",1,0) -> 1 | AC32: =IF(S32="",1,0) -> 1 | AE32: =SUM(AB32:AD32) -> 2
C36: Riesgo: | E36: Definir riesgo | G36: Prestación: | I36: Definir | O36: Tipo de contrato: | X36: =IF(AE36<>0,"Faltan datos","") -> Faltan datos | Z36: Definición | AB36: =IF(E36="Definir riesgo",1,0) -> 1 | AC36: =IF(I36="Designar tipo",1,0) -> 0 | AD36: =IF(S36="Designar tipo",1,0) -> 0 | AE36: =SUM(AB36:AD36) -> 1 | AG36: TABLA DEFINICIÓN
C38: Tareas/Exposición: | K38: Estudios: | Z38: =+S36 -> 0 | AG38: Designar tipo | AH38: Designe el tipo de contratista según las frecuencias de prestación de servicios u obras en: "Designar tipo". Consultar estandar ID 5763 - GESTÍON DE DOCUMENTACIÓN LABORAL Y SEGURIDAD SOCIAL DE CONTRATISTAS.
C40: Aplicable a todos independientemente de la tarea | I40: no | K40: Examen físico completo | O40: =IF(Tablas!$K$15=0,"no","si") -> no | Q40: Psicotécnico específico para ser brigadista | U40: =IF($I$58="si","si","no") -> no | X40: =IF(AB62=1,"Falta indicar tarea","") -> Falta indicar tarea | Z40: =IFERROR(VLOOKUP(Z38,$AG$38:$AH$50,2,FALSE),"-") -> - | AB40: =IF(I40="no",1,0) -> 1 | AG40: Permanente | AH40: Permanentes o Habituales - Contratos de obras o servicios cuya periodicidad será mensual, se realizarán en forma habitual, continuada y sin interrupciones durante la vigencia del contrato y la actividad a desarrollar demandará quince (15) o más días hábiles en cada período mensual.
C42: Conducción de Grúas, Autoelevadores, Motopala, etc | I42: no | K42: RX. Torax (F) | O42: =IF(Tablas!$K$15=0,"no","si") -> no | Q42: Hepatograma | U42: =IF($I$52="si","si","no") -> no | AB42: =IF(I42="no",1,0) -> 1 | AG42: Programado | AH42: Programados - Se considerarán dentro de este grupo, aquellas contrataciones de obras o servicios que hayan sido planificadas y cuya duración sea temporal, cuentan con un inicio y fin predeterminados. (Ej. Obras, ampliaciones, paradas de planta, perforación de pozos, trabajos de exploración, y toda otra tarea asociada a las anteriores, etc.) Carácter que lo define: Tienen un inicio y un fin predeterminado y programado, responde a un plan específico.
C44: Altura | I44: no | K44: Electrocardiograma (E.C.G) | O44: =IF(Tablas!$K$15=0,"no","si") -> no | Q44: Metabolito en orina | AB44: =IF(I44="no",1,0) -> 1 | AG44: Esporádico | AH44: Esporádicos - Contratos de servicios u obras que demanden una prestación de al menos 1 (un) día y no exceda de 20 (veinte) días en el mes, tuvieren interrupciones iguales o superiores a 1 (un) mes, entre un período de prestación y el otro. Existe certeza de que el servicio se repetirá en forma mediata pudiendo ser encomendado al mismo contratista. Carácter que lo define: Ocasional y con una interrupción mínima de la actividad de un mes entre un período y el otro.
C46: Ruido | I46: no | K46: Laboratorio | O46: =IF(Tablas!$K$15=0,"no","si") -> no | Q46: Estireno | U46: no | AB46: =IF(I46="no",1,0) -> 1 | AG46: A demanda | AH46: Contrataciones en las que el ingreso a los activos por parte de la contratista se produzca de forma excepcional, ante emergencias/urgencias técnicas, necesidades eventuales o imprevistas donde la intervención de la contratista en los activos de PAMPA no sea prolongada y no exceda los 7 días. Estas contrataciones podrían estar relacionadas con actividades como visitas técnicas, supervisión de obras o la prestación de servicios no periódicos ni regulares. Solamente podrán incluirse dentro de esta categoría aquellos casos en los que el riesgo por los servicios prestados sean Q1 o Q2.
C48: Partículas (polvo, Asbesto) | I48: no | K48: E.E.G. Informado | O48: =IF($I$42="si","si",IF($I$44="si","si",IF($I$56="si","si",IF($I$60="si","si","no")))) -> no | Q48: Etilbenceno | U48: no | AB48: =IF(I48="no",1,0) -> 1 | AG48: Reclamo Laboral | AH48: Empresa no registrada en la G&CC, se activa por Rec. Lab.
C50: Vibraciones | I50: no | K50: Exámen Clínico Neurológico Osteoarticular y circulatorio | O50: =IF($I$42="si","si",IF($I$44="si","si",IF($I$50="si","si",IF($I$56="si","si",IF($I$60="si","si","no"))))) -> no | Q50: Benceno | U50: no | AB50: =IF(I50="no",1,0) -> 1
C52: Exposiciòn quimicos e hidrocarburos | I52: no | K52: Audiometría | O52: =IF($I$42="si","si",IF($I$44="si","si",IF($I$46="si","si",IF($I$50="si","si",IF($I$56="si","si",IF($I$58="si","si",IF($I$60="si","si","no"))))))) -> no | Q52: Acrilonitrilo | U52: no | AB52: =IF(I52="no",1,0) -> 1
C54: Esfuerzo con Columna Lumbosacra | I54: no | K54: Espirometría con evaluación neumológica | O54: =IF($I$48="si","si",IF($I$50="si","si",IF($I$56="si","si",IF($I$58="si","si","no")))) -> no | Q54: Fenol | U54: no | AB54: =IF(I54="no",1,0) -> 1
C56: Espacio confinado | I56: no | K56: Rx. Columna Lumbosacra F y P | O56: =IF($I$42="si","si",IF($I$44="si","si",IF($I$50="si","si",IF($I$54="si","si",IF($I$56="si","si",IF($I$50="si","si",IF($I$58="si","si",IF($I$60="si","si","no")))))))) -> no | Q56: Hexano | U56: no | AB56: =IF(I56="no",1,0) -> 1
C58: Brigadista | I58: no | K58: Ergometria con evaluación cardiológica | O58: =IF($I$50="si","si",IF($I$56="si","si",IF($I$58="si","si","no"))) -> no | Q58: Tolueno | U58: no | AB58: =IF(I58="no",1,0) -> 1
C60: Exposición a manejo de vehículos pesados o livianos | I60: no | K60: EX. Psicologico (aptitud psicofisica) | O60: =IF($I$42="si","si",IF($I$44="si","si",IF($I$56="si","si","no"))) -> no | Q60: Xilenos | U60: no | AB60: =IF(I60="no",1,0) -> 1
K62: Electro nistagmografía | O62: =IF($I$44="si","si","no") -> no | Q62: Metabolitos de sustancias psicoactivas | U62: no | AB62: =SUM(AB40:AB60)/11 -> 1
C63: SMS
C65: Información de riesgos / Responsable / Otros | M65: Capacitación técnica básica SMS
C67: Información de seguridad de producto (FDS) | K67: no | M67: Capacitación uso adecuado EPP (Res. 905/15) | U67: no
C69: Procedimiento de tarea segura | K69: no | M69: Capacitación autocontrol preventivo (Res. 905/15) | U69: no
C71: Aviso de inicio de obra | K71: no | M71: Capacitación riesgo eléctrico (Res. 905/15) | U71: no
C73: Programa de seguridad | K73: no | M73: Capacitación manejo de extintores (Res. 905/15) | U73: no
C75: Designación responsable de seguridad | K75: no | M75: Manejo de productos químicos | U75: no
C77: Copia de matrícula del responsable seguridad | K77: no | M77: Ruido laboral e hipoacusia | U77: no
C79: Copia de matrícula del responsable de salud ocupacional | K79: no | M79: Primeros auxilios, reanimación cardiopulmonar y DEA | U79: no
C81: Video de ingreso para contratista | K81: no | M81: Manipulación manual de cargas | U81: no
C83: Constancia de entrega de EPP | K83: no | U83: no
C85: Habilitaciones | M85: Capacitación técnica específica SMS
C87: Certificado REPPSA | K87: no | M87: Capacitación permiso de trabajo | U87: no
...

Sheet Tablas
A3: Tabla I | D3: Tabla II | F3: Tabla III | H3: Tabla IV | J3: Tabla V | M3: Tabla VI | P3: Requisitos | R3: Prestación
A4: Permanente | B4: =+IF('Datos del contrato'!$S$36="Permanente","1","0") -> 0 | D4: si | F4: Q1 | H4: Ar$ | J4: Aplicable a todos independientemente de la tarea | K4: =IF('Datos del contrato'!I40="si",1,0) -> 0 | M4: Seg. Resp. Civil | P4: Apto de Salud Ocupacional (Anexo B.9) | R4: Obra | S4: =+IF('Datos del contrato'!$I$36="Obra","1","0") -> 0
A5: Programado | B5: =+IF('Datos del contrato'!$S$36="Programado","1","0") -> 0 | D5: no | F5: Q2 | H5: u$s | J5: Conducción de Grúas, Autoelevadores, Motopala, etc | K5: =IF('Datos del contrato'!I42="si",1,0) -> 0 | M5: Q1 | N5: 100000 | P5: Aviso de Inicio de Obra | R5: Servicio | S5: =+IF('Datos del contrato'!$I$36="Servicio","1","0") -> 0
A6: Esporádico | B6: =+IF('Datos del contrato'!$S$36="Esporádico","1","0") -> 0 | F6: Q3 | J6: Altura | K6: =IF('Datos del contrato'!I44="si",1,0) -> 0 | M6: Q2 | N6: 200000 | P6: Capacitación técnica básica SMS | R6: Definir | S6: =+IF('Datos del contrato'!$S$36="Esporádico","1","0") -> 0
A7: A demanda | B7: =+IF('Datos del contrato'!$S$36="A demanda","1","0") -> 0 | F7: Q4 | J7: Ruido | K7: =IF('Datos del contrato'!I46="si",1,0) -> 0 | M7: Q3 | N7: 500000 | P7: Capacitación técnica específica SMS
B8: =+IF('Datos del contrato'!$S$36="Obras","1","0") -> 0 | F8: Definir riesgo | J8: Partículas (polvo, Asbesto) | K8: =IF('Datos del contrato'!I48="si",1,0) -> 0 | M8: Q4 | N8: 1000000 | P8: Constancia de entrega de EPP
B9: =+IF('Datos del contrato'!$S$36="Servicios","1","0") -> 0 | J9: Vibraciones | K9: =IF('Datos del contrato'!I50="si",1,0) -> 0 | M9: Definir riesgo | N9: 0 | P9: Designación responsable seguridad
J10: Exposiciòn quimicos e hidrocarburos | K10: =IF('Datos del contrato'!I52="si",1,0) -> 0 | P10: Programa de Seguridad
J11: Esfuerzo con Columna Lumbosacra | K11: =IF('Datos del contrato'!I54="si",1,0) -> 0 | P11: Copia de matrícula del Responsable seguridad
J12: Espacio confinado | K12: =IF('Datos del contrato'!I56="si",1,0) -> 0
J13: Brigadista | K13: =IF('Datos del contrato'!I58="si",1,0) -> 0
J14: Exposición a manejo de vehículos pesados o livianos | K14: =IF('Datos del contrato'!I60="si",1,0) -> 0
J15: Total | K15: =SUM(K4:K14) -> 0

Sheet Hoja1
B4: Requisitos SMS PGSM
A5: x | B5: Fotocopia Responsable en Seguridad | H5: APLICA A EMPRESA
A6: x | B6: Matricula pago año en curso del Resp Seguridad | H6: APLICA A EMPRESA
A7: x | B7: Programa Seguidad generico 51/97 - 911/96 (aprobado por ART) | H7: APLICA EMPRESA
A8: agregar | B8: Titulo del tecnico en seguridad | H8: APLICA PERSONA
A9: x | B9: Induccion planta | H9: APLICA A PERSONA
B10: Programa de tareas (recepcionado por ART) | H10: APLICA EMPRESA
A11: x | B11: Aviso inicio obra (recepcionado por ART) | H11: APLICA EMPRESA
B12: Programa Seguidad generico 51/97 - 911/96 (aprobado por ART) | H12: APLICA EMPRESA
A13: x | B13: Constancia de capacitación sobre Normas Básicas de Seguridad de Pampa Energía SA y Sistemas de Alarmas firmadas por el Responsable de Seguridad y por cada una de las personas que ingresarán. | H13: APLICA PERSONA
A14: x | B14: Constancia de entrega y capacitación en uso de EPPs | H14: APLICA PERSONA
B15: Curso Capacitación Básica de Seguridad, dictada por la Cámara de Comercio de San Lorenzo. Solo aplica a los contratos encuadrados como QIII y QIV | H15: APLICA PERSONA
C17: Requisitros SMS activados en Certronic | I17: Requisitros SMS
C18: Certificado RENPRE | I18: Aviso de inicio de obra
C19: Certificado RePGTyORE operador | I19: Programa de Seguridad
C20: Certificado RePGTyORE transportista | I20: Copia de matrícula del Responsable seguridad
C21: Certificado REPSSA | I21: Curso de buenas prácticas de manufactura
C22: Designacion responsable seguridad | I22: Video de ingreso para contratistas
C23: Fichas datos seguridad | I23: Capacitación técnica básica SMS
C24: Habilitación Serv. recoleccion de residuos | I24: Capacitación técnica específica SMS
C25: Hoja de seguridad MSDS | I25: Constancia de entrega de EPP
C26: Identificación peligro y eval riesgo | I26: Información de seguridad de producto (FDS)
C27: Lic. Bromatológica | I27: Habilitación para manejo de equipos de izaje
C28: Lic. Comercial para el Control de Plagas | I28: Control de herramientas
... C35: Curso de Inducción | I35: VTV
C36: Registro Capacitación
C37: Carnet manejo especial
C38: Const. de Entrega de Ropa de Trabajo y EPP
C39: Lic. Nacional de conducir.
C40: Lic. Nacional Habilitante (CNRT)
C41: Informe responsable seguridad
C42: Inspección arnes seguridad
C43: Inspección equipos izaje
C44: Inspección escaleras
C45: Inspección herramientas y maquinarias
C46: Inspección tableros eléctricos
C47: Certificado de Calibracion
... C49: VTV
